Workbook
Name ALT: 氏名!#REF!
Name AZURE・PLUS: 氏名!#REF!
Name FPTジャパン: 氏名!$D$2:$D$59
Name GEL研究所: 氏名!#REF!
Name miracleave: 氏名!#REF!
Name MSI: 氏名!#REF!
Name MWI: 氏名!#REF!
Name NTC: 氏名!#REF!
Name Sharing_Innovations: 氏名!#REF!
Name SHIFT: 氏名!#REF!
Name SIG: 氏名!#REF!
Name XspearConsulting: 氏名!#REF!
Name アイビス: 氏名!#REF!
Name アヴァンティスタッフ: 氏名!#REF!
Name アクサス: 氏名!#REF!
Name アドマックス: 氏名!#REF!
Name インプレス: 氏名!#REF!
Name エイシル: 氏名!#REF!
Name エヌエス・フューチャー: 氏名!#REF!
Name サイバーコム: 氏名!#REF!
Name サンアイエンジニアリング: 氏名!#REF!
Name ジーソル: 氏名!#REF!
Name システムコード: PJ!$A:$C
Name システムコード: PJ!$A:$C
Name システムプロダクツ: 氏名!#REF!
Name スタッフサービス: 氏名!#REF!
Name ステップITソリューション: 氏名!#REF!
Name スリーエース: 氏名!#REF!
Name ソフトテックス: 氏名!#REF!
Name タクミコーポレーション: 氏名!#REF!
Name テクノプロ: 氏名!#REF!
Name テックビズ: 氏名!#REF!
Name トライベック: 氏名!#REF!
Name ネオテックス: 氏名!#REF!
Name パーソルテクノロジースタッフ: 氏名!#REF!
Name プライマル: 氏名!#REF!
Name プライム: 氏名!#REF!
Name ブレーク: 氏名!#REF!
Name プロジェクトWORK: PJ!$A$2:$D$2
Name プロジェクトコード: PJ!$D:$D
Name プロジェクトコード: PJ!$D:$D
Name ラクスパートナーズ: 氏名!#REF!
Name リード: 氏名!#REF!
Name リクルートスタッフィング: 氏名!#REF!
Name 会社名: 会社名!$B$2:$B$2
Name 工種_間接: 工種!$B$77:$B$83
Name 工種_全部: 工種!$B$2:$B$83
Name 工種_通常: 工種!$B$2:$B$76
Name 社員名: [1]所属!$A$2:$A$303
Name 綜合システム開発: 氏名!#REF!
Name 日本ラッド: 氏名!#REF!

Sheet 1週
A1: 週間進捗状況報告書
T2: 管理者 | W2: 本人
B3: 2026 | C3: 7
C4: =IF(C3="","",IF(U9="","",1)) -> 1
B6: 会社名 | C6: FPTジャパン | D6: =IFERROR(INDEX(会社名!A:A,MATCH(C6,会社名!B:B,0),1),"") -> 10000
B7: 氏名 | C7: Nguyen Hoang Nam | D7: BA
I8: 月 | K8: 火 | M8: 水 | O8: 木 | Q8: 金 | S8: 土 | U8: 日
I9: =IF(WEEKDAY($B$3&"/"&$C$3&"/"&1)=2,1,"") | K9: =IF(I9<>"",I9+1,IF(WEEKDAY($B$3&"/"&$C$3&"/"&1)=3,1,"")) | M9: =IF(K9<>"",K9+1,IF(WEEKDAY($B$3&"/"&$C$3&"/"&1)=4,1,"")) -> 1 | O9: =IF(M9<>"",M9+1,IF(WEEKDAY($B$3&"/"&$C$3&"/"&1)=5,1,"")) -> 2 | Q9: =IF(O9<>"",O9+1,IF(WEEKDAY($B$3&"/"&$C$3&"/"&1)=6,1,"")) -> 3 | S9: =IF(Q9<>"",Q9+1,IF(WEEKDAY($B$3&"/"&$C$3&"/"&1)=7,1,"")) -> 4 | U9: =IF(S9<>"",S9+1,IF(WEEKDAY($B$3&"/"&$C$3&"/"&1)=1,1,"")) -> 5
A10: No | B10: システムコード | C10: システム名 | D10: 工種コード | E10: 主な作業内容（予定） | F10: 予定 | G10: 始業 | M10: 0.375 | O10: 0.375 | Q10: 0.375 | W10: 累計
B11: プロジェクトコード | C11: プロジェクト名 | D11: 工種 | F11: 達成度 | G11: 終業 | M11: 0.77083333 | O11: 0.77083333 | Q11: 0.77083333 | W11: =W13 -> 1.875
F12: 休憩・外出時間 | M12: 0.041666667 | O12: 0.041666667 | Q12: 0.041666667 | W12: 合計
A13: 合計 | I13: =TIMEVALUE(TEXT(I11-I10-I12,"h:mm:ss")) -> 0.375 | K13: =TIMEVALUE(TEXT(K11-K10-K12,"h:mm:ss")) -> 0.375 | M13: =TIMEVALUE(TEXT(M11-M10-M12,"h:mm:ss")) -> 0.375 | O13: =TIMEVALUE(TEXT(O11-O10-O12,"h:mm:ss")) -> 0.375 | Q13: =TIMEVALUE(TEXT(Q11-Q10-Q12,"h:mm:ss")) -> 0.375 | S13: =TIMEVALUE(TEXT(S11-S10-S12,"h:mm:ss")) -> 0 | U13: =TIMEVALUE(TEXT(U11-U10-U12,"h:mm:ss")) -> 0 | W13: =CEILING(SUM(I13:V13),"0:5") -> 1.875
A15: 1 | B15: =IF($B16="","",INDEX(PJ!$A:$A,MATCH(B16,PJ!$C:$C,0))) -> 10000 | C15: =IF($B16="","",INDEX(PJ!$B:$B,MATCH(B16, PJ!$C:$C, 0))) -> Yokogawa | D15: =IF(D16="","",INDEX(工種!$A$2:$A$83,MATCH(D16,工種!$B$2:$B$83,0),1)) -> 10102 | G15: 予定
B16: 10000 | C16: =IF($B16="","",INDEX(PJ!$D:$D,MATCH(B16, PJ!$C:$C, 0))) -> Rep Portal | D16: 製造：コーディング | E16: コーディング | G16: 実績 | M16: 0.27083333 | O16: 0.27083333 | Q16: 0.27083333 | W16: =SUM(I16:V16) -> 0
A17: 2 | B17: =IF($B18="","",INDEX(PJ!$A:$A,MATCH(B18,PJ!$C:$C,0))) -> 10000 | C17: =IF($B18="","",INDEX(PJ!$B:$B,MATCH(B18, PJ!$C:$C, 0))) -> Yokogawa | D17: =IF(D18="","",INDEX(工種!$A$2:$A$83,MATCH(D18,工種!$B$2:$B$83,0),1)) -> 30106 | G17: 予定
B18: 10000 | C18: =IF($B18="","",INDEX(PJ!$D:$D,MATCH(B18, PJ!$C:$C, 0))) -> Rep Portal | D18: テスト：結合テスト実施 | E18: 結合テスト実施 | G18: 実績 | M18: 0.083333333 | O18: 0.083333333 | Q18: 0.083333333 | W18: =SUM(I18:V18) -> 0
A19: 3 | B19: =IF($B20="","",INDEX(PJ!$A:$A,MATCH(B20,PJ!$C:$C,0))) -> 10000 | C19: =IF($B20="","",INDEX(PJ!$B:$B,MATCH(B20, PJ!$C:$C, 0))) -> Yokogawa | D19: =IF(D20="","",INDEX(工種!$A$2:$A$83,MATCH(D20,工種!$B$2:$B$83,0),1)) -> 40108 | G19: 予定
C20: =IF($B20="","",INDEX(PJ!$D:$D,MATCH(B20, PJ!$C:$C, 0))) -> Rep Portal | G20: 実績 | W20: =SUM(I20:V20) -> 0
A21: 4 | B21: =IF($B22="","",INDEX(PJ!$A:$A,MATCH(B22,PJ!$C:$C,0))) | C21: =IF($B22="","",INDEX(PJ!$B:$B,MATCH(B22, PJ!$C:$C, 0))) | D21: =IF(D22="","",INDEX(工種!$A$2:$A$83,MATCH(D22,工種!$B$2:$B$83,0),1)) | G21: 予定
C22: =IF($B22="","",INDEX(PJ!$D:$D,MATCH(B22, PJ!$C:$C, 0))) | G22: 実績 | W22: =SUM(I22:V22) -> 0
A23: 5 | B23: =IF($B24="","",INDEX(PJ!$A:$A,MATCH(B24,PJ!$C:$C,0))) | C23: =IF($B24="","",INDEX(PJ!$B:$B,MATCH(B24, PJ!$C:$C, 0))) | D23: =IF(D24="","",INDEX(工種!$A$2:$A$83,MATCH(D24,工種!$B$2:$B$83,0),1)) | G23: 予定
C24: =IF($B24="","",INDEX(PJ!$D:$D,MATCH(B24, PJ!$C:$C, 0))) | G24: 実績 | W24: =SUM(I24:V24) -> 0
A25: 6 | B25: =IF($B26="","",INDEX(PJ!$A:$A,MATCH(B26,PJ!$C:$C,0))) | C25: =IF($B26="","",INDEX(PJ!$B:$B,MATCH(B26, PJ!$C:$C, 0))) | D25: =IF(D26="","",INDEX(工種!$A$2:$A$83,MATCH(D26,工種!$B$2:$B$83,0),1)) | G25: 予定
C26: =IF($B26="","",INDEX(PJ!$D:$D,MATCH(B26, PJ!$C:$C, 0))) | G26: 実績 | W26: =SUM(I26:V26) -> 0
A27: 7 | B27: =IF($B28="","",INDEX(PJ!$A:$A,MATCH(B28,PJ!$C:$C,0))) | C27: =IF($B28="","",INDEX(PJ!$B:$B,MATCH(B28, PJ!$C:$C, 0))) | D27: =IF(D28="","",INDEX(工種!$A$2:$A$83,MATCH(D28,工種!$B$2:$B$83,0),1)) | G27: 予定
C28: =IF($B28="","",INDEX(PJ!$D:$D,MATCH(B28, PJ!$C:$C, 0))) | G28: 実績 | W28: =SUM(I28:V28) -> 0
A29: 8 | B29: =IF($B30="","",INDEX(PJ!$A:$A,MATCH(B30,PJ!$C:$C,0))) | C29: =IF($B30="","",INDEX(PJ!$B:$B,MATCH(B30, PJ!$C:$C, 0))) | D29: =IF(D30="","",INDEX(工種!$A$2:$A$83,MATCH(D30,工種!$B$2:$B$83,0),1)) | G29: 予定
C30: =IF($B30="","",INDEX(PJ!$D:$D,MATCH(B30, PJ!$C:$C, 0))) | G30: 実績 | W30: =SUM(I30:V30) -> 0
A31: 9 | B31: =IF($B32="","",INDEX(PJ!$A:$A,MATCH(B32,PJ!$C:$C,0))) | C31: =IF($B32="","",INDEX(PJ!$B:$B,MATCH(B32, PJ!$C:$C, 0))) | D31: =IF(D32="","",INDEX(工種!$A$2:$A$83,MATCH(D32,工種!$B$2:$B$83,0),1)) | G31: 予定
C32: =IF($B32="","",INDEX(PJ!$D:$D,MATCH(B32, PJ!$C:$C, 0))) | G32: 実績 | W32: =SUM(I32:V32) -> 0
A33: 10 | B33: =IF($B34="","",INDEX(PJ!$A:$A,MATCH(B34,PJ!$C:$C,0))) | C33: =IF($B34="","",INDEX(PJ!$B:$B,MATCH(B34, PJ!$C:$C, 0))) | D33: =IF(D34="","",INDEX(工種!$A$2:$A$83,MATCH(D34,工種!$B$2:$B$83,0),1)) | G33: 予定
C34: =IF($B34="","",INDEX(PJ!$D:$D,MATCH(B34, PJ!$C:$C, 0))) | G34: 実績 | W34: =SUM(I34:V34) -> 0
A35: 11 | B35: =IF($B36="","",INDEX(PJ!$A:$A,MATCH(B36,PJ!$C:$C,0))) | C35: =IF($B36="","",INDEX(PJ!$B:$B,MATCH(B36, PJ!$C:$C, 0))) | D35: =IF(D36="","",INDEX(工種!$A$2:$A$83,MATCH(D36,工種!$B$2:$B$83,0),1)) | G35: 予定
C36: =IF($B36="","",INDEX(PJ!$D:$D,MATCH(B36, PJ!$C:$C, 0))) | G36: 実績 | W36: =SUM(I36:V36) -> 0
A37: 12 | B37: =IF($B38="","",INDEX(PJ!$A:$A,MATCH(B38,PJ!$C:$C,0))) | C37: =IF($B38="","",INDEX(PJ!$B:$B,MATCH(B38, PJ!$C:$C, 0))) | D37: =IF(D38="","",INDEX(工種!$A$2:$A$83,MATCH(D38,工種!$B$2:$B$83,0),1)) | G37: 予定
C38: =IF($B38="","",INDEX(PJ!$D:$D,MATCH(B38, PJ!$C:$C, 0))) | G38: 実績 | W38: =SUM(I38:V38) -> 0
A39: 13 | B39: =IF($B40="","",INDEX(PJ!$A:$A,MATCH(B40,PJ!$C:$C,0))) | C39: =IF($B40="","",INDEX(PJ!$B:$B,MATCH(B40, PJ!$C:$C, 0))) | D39: =IF(D40="","",INDEX(工種!$A$2:$A$83,MATCH(D40,工種!$B$2:$B$83,0),1)) | G39: 予定
C40: =IF($B40="","",INDEX(PJ!$D:$D,MATCH(B40, PJ!$C:$C, 0))) | G40: 実績 | W40: =SUM(I40:V40) -> 0
A41: 14 | B41: =IF($B42="","",INDEX(PJ!$A:$A,MATCH(B42,PJ!$C:$C,0))) | C41: =IF($B42="","",INDEX(PJ!$B:$B,MATCH(B42, PJ!$C:$C, 0))) | D41: =IF(D42="","",INDEX(工種!$A$2:$A$83,MATCH(D42,工種!$B$2:$B$83,0),1)) | G41: 予定
C42: =IF($B42="","",INDEX(PJ!$D:$D,MATCH(B42, PJ!$C:$C, 0))) | G42: 実績 | W42: =SUM(I42:V42) -> 0
...

Sheet 2週
A1: 週間進捗状況報告書
T2: 管理者 | W2: 本人
B3: ='1週'!B3 -> 2026 | C3: ='1週'!C3 -> 7
C4: =IF('1週'!C3="","",IF('1週'!C4=1,2,1)) -> 2
B6: 会社名 | C6: ='1週'!C6 -> FPTジャパン
B7: 氏名 | C7: ='1週'!C7 -> LE NHUT THIEN
I8: 月 | K8: 火 | M8: 水 | O8: 木 | Q8: 金 | S8: 土 | U8: 日
I9: ='1週'!U9+1 -> 6 | K9: =I9+1 -> 7 | M9: =K9+1 -> 8 | O9: =M9+1 -> 9 | Q9: =O9+1 -> 10 | S9: =Q9+1 -> 11 | U9: =S9+1 -> 12
A10: No | B10: システムコード | C10: システム名 | D10: 工種コード | E10: 主な作業内容（予定） | F10: 予定 | G10: 始業 | I10: 0.375 | K10: 0.375 | M10: 0.375 | O10: 0.375 | Q10: 0.375 | W10: 累計
B11: プロジェクトコード | C11: プロジェクト名 | D11: 工種 | F11: 達成度 | G11: 終業 | I11: 0.77083333 | K11: 0.77083333 | M11: 0.77083333 | O11: 0.77083333 | Q11: 0.54166667 | W11: ='1週'!W11+W13 -> 3.75
F12: 休憩・外出時間 | I12: 0.041666667 | K12: 0.041666667 | M12: 0.041666667 | O12: 0.041666667 | Q12: 0.041666667 | W12: 合計
A13: 合計 | I13: =TIMEVALUE(TEXT(I11-I10-I12,"h:mm:ss")) -> 0.375 | K13: =TIMEVALUE(TEXT(K11-K10-K12,"h:mm:ss")) -> 0.375 | M13: =TIMEVALUE(TEXT(M11-M10-M12,"h:mm:ss")) -> 0.375 | O13: =TIMEVALUE(TEXT(O11-O10-O12,"h:mm:ss")) -> 0.375 | Q13: =TIMEVALUE(TEXT(Q11-Q10-Q12,"h:mm:ss")) -> 0.375 | S13: =TIMEVALUE(TEXT(S11-S10-S12,"h:mm:ss")) -> 0 | U13: =TIMEVALUE(TEXT(U11-U10-U12,"h:mm:ss")) -> 0 | W13: =CEILING(SUM(I13:V13),"0:5") -> 1.875
A15: 1 | B15: =IF($B16="","",INDEX(PJ!$A:$A,MATCH(B16,PJ!$C:$C,0))) -> 10000 | C15: =IF($B16="","",INDEX(PJ!$B:$B,MATCH(B16, PJ!$C:$C, 0))) -> Yokogawa | D15: =IF(D16="","",INDEX(工種!$A$2:$A$83,MATCH(D16,工種!$B$2:$B$83,0),1)) -> 10102 | G15: 予定
B16: 10000 | C16: =IF($B16="","",INDEX(PJ!$D:$D,MATCH(B16, PJ!$C:$C, 0))) -> Rep Portal | D16: 製造：コーディング | E16: コーディング | G16: 実績 | I16: 0.27083333 | K16: 0.27083333 | M16: 0.27083333 | O16: 0.27083333 | Q16: 0.125 | W16: =SUM(I16:V16) -> 1.0416667
A17: 2 | B17: =IF($B18="","",INDEX(PJ!$A:$A,MATCH(B18,PJ!$C:$C,0))) -> 10000 | C17: =IF($B18="","",INDEX(PJ!$B:$B,MATCH(B18, PJ!$C:$C, 0))) -> Yokogawa | D17: =IF(D18="","",INDEX(工種!$A$2:$A$83,MATCH(D18,工種!$B$2:$B$83,0),1)) -> 30106 | G17: 予定
B18: 10000 | C18: =IF($B18="","",INDEX(PJ!$D:$D,MATCH(B18, PJ!$C:$C, 0))) -> Rep Portal | D18: テスト：結合テスト実施 | E18: 結合テスト実施 | G18: 実績 | I18: 0.083333333 | K18: 0.083333333 | M18: 0.083333333 | O18: 0.083333333 | W18: =SUM(I18:V18) -> 0.625
A19: 3 | B19: =IF($B20="","",INDEX(PJ!$A:$A,MATCH(B20,PJ!$C:$C,0))) -> 10000 | C19: =IF($B20="","",INDEX(PJ!$B:$B,MATCH(B20, PJ!$C:$C, 0))) -> Yokogawa | D19: =IF(D20="","",INDEX(工種!$A$2:$A$83,MATCH(D20,工種!$B$2:$B$83,0),1)) -> 40108 | G19: 予定
C20: =IF($B20="","",INDEX(PJ!$D:$D,MATCH(B20, PJ!$C:$C, 0))) -> Rep Portal | G20: 実績 | W20: =SUM(I20:V20) -> 0.52083333
A21: 4 | G21: 予定
G22: 実績 | W22: =SUM(I22:V22) -> 0
A23: 5 | B23: =IF($B24="","",INDEX(PJ!$A:$A,MATCH(B24,PJ!$C:$C,0))) | C23: =IF($B24="","",INDEX(PJ!$B:$B,MATCH(B24, PJ!$C:$C, 0))) | D23: =IF(D24="","",INDEX(工種!$A$2:$A$83,MATCH(D24,工種!$B$2:$B$83,0),1)) | G23: 予定
C24: =IF($B24="","",INDEX(PJ!$D:$D,MATCH(B24, PJ!$C:$C, 0))) | G24: 実績 | W24: =SUM(I24:V24) -> 0
A25: 6 | B25: =IF($B26="","",INDEX(PJ!$A:$A,MATCH(B26,PJ!$C:$C,0))) | C25: =IF($B26="","",INDEX(PJ!$B:$B,MATCH(B26, PJ!$C:$C, 0))) | D25: =IF(D26="","",INDEX(工種!$A$2:$A$83,MATCH(D26,工種!$B$2:$B$83,0),1)) | G25: 予定
C26: =IF($B26="","",INDEX(PJ!$D:$D,MATCH(B26, PJ!$C:$C, 0))) | G26: 実績 | W26: =SUM(I26:V26) -> 0
A27: 7 | B27: =IF($B28="","",INDEX(PJ!$A:$A,MATCH(B28,PJ!$C:$C,0))) | C27: =IF($B28="","",INDEX(PJ!$B:$B,MATCH(B28, PJ!$C:$C, 0))) | D27: =IF(D28="","",INDEX(工種!$A$2:$A$83,MATCH(D28,工種!$B$2:$B$83,0),1)) | G27: 予定
C28: =IF($B28="","",INDEX(PJ!$D:$D,MATCH(B28, PJ!$C:$C, 0))) | G28: 実績 | W28: =SUM(I28:V28) -> 0
A29: 8 | B29: =IF($B30="","",INDEX(PJ!$A:$A,MATCH(B30,PJ!$C:$C,0))) | C29: =IF($B30="","",INDEX(PJ!$B:$B,MATCH(B30, PJ!$C:$C, 0))) | D29: =IF(D30="","",INDEX(工種!$A$2:$A$83,MATCH(D30,工種!$B$2:$B$83,0),1)) | G29: 予定
C30: =IF($B30="","",INDEX(PJ!$D:$D,MATCH(B30, PJ!$C:$C, 0))) | G30: 実績 | W30: =SUM(I30:V30) -> 0
A31: 9 | B31: =IF($B32="","",INDEX(PJ!$A:$A,MATCH(B32,PJ!$C:$C,0))) | C31: =IF($B32="","",INDEX(PJ!$B:$B,MATCH(B32, PJ!$C:$C, 0))) | D31: =IF(D32="","",INDEX(工種!$A$2:$A$83,MATCH(D32,工種!$B$2:$B$83,0),1)) | G31: 予定
C32: =IF($B32="","",INDEX(PJ!$D:$D,MATCH(B32, PJ!$C:$C, 0))) | G32: 実績 | W32: =SUM(I32:V32) -> 0
A33: 10 | B33: =IF($B34="","",INDEX(PJ!$A:$A,MATCH(B34,PJ!$C:$C,0))) | C33: =IF($B34="","",INDEX(PJ!$B:$B,MATCH(B34, PJ!$C:$C, 0))) | D33: =IF(D34="","",INDEX(工種!$A$2:$A$83,MATCH(D34,工種!$B$2:$B$83,0),1)) | G33: 予定
C34: =IF($B34="","",INDEX(PJ!$D:$D,MATCH(B34, PJ!$C:$C, 0))) | G34: 実績 | W34: =SUM(I34:V34) -> 0
A35: 11 | B35: =IF($B36="","",INDEX(PJ!$A:$A,MATCH(B36,PJ!$C:$C,0))) | C35: =IF($B36="","",INDEX(PJ!$B:$B,MATCH(B36, PJ!$C:$C, 0))) | D35: =IF(D36="","",INDEX(工種!$A$2:$A$83,MATCH(D36,工種!$B$2:$B$83,0),1)) | G35: 予定
C36: =IF($B36="","",INDEX(PJ!$D:$D,MATCH(B36, PJ!$C:$C, 0))) | G36: 実績 | W36: =SUM(I36:V36) -> 0
A37: 12 | B37: =IF($B38="","",INDEX(PJ!$A:$A,MATCH(B38,PJ!$C:$C,0))) | C37: =IF($B38="","",INDEX(PJ!$B:$B,MATCH(B38, PJ!$C:$C, 0))) | D37: =IF(D38="","",INDEX(工種!$A$2:$A$83,MATCH(D38,工種!$B$2:$B$83,0),1)) | G37: 予定
C38: =IF($B38="","",INDEX(PJ!$D:$D,MATCH(B38, PJ!$C:$C, 0))) | G38: 実績 | W38: =SUM(I38:V38) -> 0
A39: 13 | B39: =IF($B40="","",INDEX(PJ!$A:$A,MATCH(B40,PJ!$C:$C,0))) | C39: =IF($B40="","",INDEX(PJ!$B:$B,MATCH(B40, PJ!$C:$C, 0))) | D39: =IF(D40="","",INDEX(工種!$A$2:$A$83,MATCH(D40,工種!$B$2:$B$83,0),1)) | G39: 予定
C40: =IF($B40="","",INDEX(PJ!$D:$D,MATCH(B40, PJ!$C:$C, 0))) | G40: 実績 | W40: =SUM(I40:V40) -> 0
A41: 14 | B41: =IF($B42="","",INDEX(PJ!$A:$A,MATCH(B42,PJ!$C:$C,0))) | C41: =IF($B42="","",INDEX(PJ!$B:$B,MATCH(B42, PJ!$C:$C, 0))) | D41: =IF(D42="","",INDEX(工種!$A$2:$A$83,MATCH(D42,工種!$B$2:$B$83,0),1)) | G41: 予定
C42: =IF($B42="","",INDEX(PJ!$D:$D,MATCH(B42, PJ!$C:$C, 0))) | G42: 実績 | W42: =SUM(I42:V42) -> 0
...

Sheet 3週
A1: 週間進捗状況報告書
T2: 管理者 | W2: 本人
B3: ='1週'!B3 -> 2026 | C3: ='1週'!C3 -> 7
C4: =IF('1週'!C3="","",IF('1週'!C4=1,3,2)) -> 3
B6: 会社名 | C6: ='1週'!C6 -> FPTジャパン
B7: 氏名 | C7: ='1週'!C7 -> LE NHUT THIEN
I8: 月 | K8: 火 | M8: 水 | O8: 木 | Q8: 金 | S8: 土 | U8: 日
I9: ='2週'!U9+1 -> 13 | K9: =I9+1 -> 14 | M9: =K9+1 -> 15 | O9: =M9+1 -> 16 | Q9: =O9+1 -> 17 | S9: =Q9+1 -> 18 | U9: =S9+1 -> 19
A10: No | B10: システムコード | C10: システム名 | D10: 工種コード | E10: 主な作業内容（予定） | F10: 予定 | G10: 始業 | I10: 0.375 | K10: 0.375 | M10: 0.375 | O10: 0.375 | Q10: 0.375 | W10: 累計
B11: プロジェクトコード | C11: プロジェクト名 | D11: 工種 | F11: 達成度 | G11: 終業 | I11: 0.77083333 | K11: 0.77083333 | M11: 0.77083333 | O11: 0.77083333 | Q11: 0.77083333 | W11: ='2週'!W11+W13 -> 5.625
F12: 休憩・外出時間 | I12: 0.041666667 | K12: 0.041666667 | M12: 0.041666667 | O12: 0.041666667 | Q12: 0.041666667 | W12: 合計
A13: 合計 | I13: =TIMEVALUE(TEXT(I11-I10-I12,"h:mm:ss")) -> 0.375 | K13: =TIMEVALUE(TEXT(K11-K10-K12,"h:mm:ss")) -> 0.375 | M13: =TIMEVALUE(TEXT(M11-M10-M12,"h:mm:ss")) -> 0.375 | O13: =TIMEVALUE(TEXT(O11-O10-O12,"h:mm:ss")) -> 0.375 | Q13: =TIMEVALUE(TEXT(Q11-Q10-Q12,"h:mm:ss")) -> 0.375 | S13: =TIMEVALUE(TEXT(S11-S10-S12,"h:mm:ss")) -> 0 | U13: =TIMEVALUE(TEXT(U11-U10-U12,"h:mm:ss")) -> 0 | W13: =CEILING(SUM(I13:V13),"0:5") -> 1.875
A15: 1 | B15: =IF($B16="","",INDEX(PJ!$A:$A,MATCH(B16,PJ!$C:$C,0))) -> 10000 | C15: =IF($B16="","",INDEX(PJ!$B:$B,MATCH(B16, PJ!$C:$C, 0))) -> Yokogawa | D15: =IF(D16="","",INDEX(工種!$A$2:$A$83,MATCH(D16,工種!$B$2:$B$83,0),1)) -> 10102 | G15: 予定
B16: 10000 | C16: =IF($B16="","",INDEX(PJ!$D:$D,MATCH(B16, PJ!$C:$C, 0))) -> Rep Portal | D16: 製造：コーディング | E16: コーディング | G16: 実績 | I16: 0.27083333 | K16: 0.27083333 | M16: 0.22916667 | O16: 0.27083333 | Q16: 0.27083333 | W16: =SUM(I16:V16) -> 1.0416667
A17: 2 | B17: =IF($B18="","",INDEX(PJ!$A:$A,MATCH(B18,PJ!$C:$C,0))) -> 10000 | C17: =IF($B18="","",INDEX(PJ!$B:$B,MATCH(B18, PJ!$C:$C, 0))) -> Yokogawa | D17: =IF(D18="","",INDEX(工種!$A$2:$A$83,MATCH(D18,工種!$B$2:$B$83,0),1)) -> 30106 | G17: 予定
B18: 10000 | C18: =IF($B18="","",INDEX(PJ!$D:$D,MATCH(B18, PJ!$C:$C, 0))) -> Rep Portal | D18: テスト：結合テスト実施 | E18: 結合テスト実施 | G18: 実績 | I18: 0.083333333 | K18: 0.083333333 | M18: 0.083333333 | O18: 0.083333333 | Q18: 0.083333333 | W18: =SUM(I18:V18) -> 0.625
A19: 3 | B19: =IF($B20="","",INDEX(PJ!$A:$A,MATCH(B20,PJ!$C:$C,0))) -> 10000 | C19: =IF($B20="","",INDEX(PJ!$B:$B,MATCH(B20, PJ!$C:$C, 0))) -> Yokogawa | D19: =IF(D20="","",INDEX(工種!$A$2:$A$83,MATCH(D20,工種!$B$2:$B$83,0),1)) -> 40108 | G19: 予定
B20: 10000 | C20: =IF($B20="","",INDEX(PJ!$D:$D,MATCH(B20, PJ!$C:$C, 0))) -> Rep Portal | D20: 管理業務：打合せ | E20: 打合せ | G20: 実績 | M20: 0.041666667 | W20: =SUM(I20:V20) -> 0.52083333
A21: 4 | B21: =IF($B22="","",INDEX(PJ!$A:$A,MATCH(B22,PJ!$C:$C,0))) | C21: =IF($B22="","",INDEX(PJ!$B:$B,MATCH(B22, PJ!$C:$C, 0))) | D21: =IF(D22="","",INDEX(工種!$A$2:$A$83,MATCH(D22,工種!$B$2:$B$83,0),1)) | G21: 予定
C22: =IF($B22="","",INDEX(PJ!$D:$D,MATCH(B22, PJ!$C:$C, 0))) | G22: 実績 | W22: =SUM(I22:V22) -> 0
A23: 5 | B23: =IF($B24="","",INDEX(PJ!$A:$A,MATCH(B24,PJ!$C:$C,0))) | C23: =IF($B24="","",INDEX(PJ!$B:$B,MATCH(B24, PJ!$C:$C, 0))) | D23: =IF(D24="","",INDEX(工種!$A$2:$A$83,MATCH(D24,工種!$B$2:$B$83,0),1)) | G23: 予定
C24: =IF($B24="","",INDEX(PJ!$D:$D,MATCH(B24, PJ!$C:$C, 0))) | G24: 実績 | W24: =SUM(I24:V24) -> 0
A25: 6 | B25: =IF($B26="","",INDEX(PJ!$A:$A,MATCH(B26,PJ!$C:$C,0))) | C25: =IF($B26="","",INDEX(PJ!$B:$B,MATCH(B26, PJ!$C:$C, 0))) | D25: =IF(D26="","",INDEX(工種!$A$2:$A$83,MATCH(D26,工種!$B$2:$B$83,0),1)) | G25: 予定
C26: =IF($B26="","",INDEX(PJ!$D:$D,MATCH(B26, PJ!$C:$C, 0))) | G26: 実績 | W26: =SUM(I26:V26) -> 0
A27: 7 | B27: =IF($B28="","",INDEX(PJ!$A:$A,MATCH(B28,PJ!$C:$C,0))) | C27: =IF($B28="","",INDEX(PJ!$B:$B,MATCH(B28, PJ!$C:$C, 0))) | D27: =IF(D28="","",INDEX(工種!$A$2:$A$83,MATCH(D28,工種!$B$2:$B$83,0),1)) | G27: 予定
C28: =IF($B28="","",INDEX(PJ!$D:$D,MATCH(B28, PJ!$C:$C, 0))) | G28: 実績 | W28: =SUM(I28:V28) -> 0
A29: 8 | B29: =IF($B30="","",INDEX(PJ!$A:$A,MATCH(B30,PJ!$C:$C,0))) | C29: =IF($B30="","",INDEX(PJ!$B:$B,MATCH(B30, PJ!$C:$C, 0))) | D29: =IF(D30="","",INDEX(工種!$A$2:$A$83,MATCH(D30,工種!$B$2:$B$83,0),1)) | G29: 予定
C30: =IF($B30="","",INDEX(PJ!$D:$D,MATCH(B30, PJ!$C:$C, 0))) | G30: 実績 | W30: =SUM(I30:V30) -> 0
A31: 9 | B31: =IF($B32="","",INDEX(PJ!$A:$A,MATCH(B32,PJ!$C:$C,0))) | C31: =IF($B32="","",INDEX(PJ!$B:$B,MATCH(B32, PJ!$C:$C, 0))) | D31: =IF(D32="","",INDEX(工種!$A$2:$A$83,MATCH(D32,工種!$B$2:$B$83,0),1)) | G31: 予定
C32: =IF($B32="","",INDEX(PJ!$D:$D,MATCH(B32, PJ!$C:$C, 0))) | G32: 実績 | W32: =SUM(I32:V32) -> 0
A33: 10 | B33: =IF($B34="","",INDEX(PJ!$A:$A,MATCH(B34,PJ!$C:$C,0))) | C33: =IF($B34="","",INDEX(PJ!$B:$B,MATCH(B34, PJ!$C:$C, 0))) | D33: =IF(D34="","",INDEX(工種!$A$2:$A$83,MATCH(D34,工種!$B$2:$B$83,0),1)) | G33: 予定
C34: =IF($B34="","",INDEX(PJ!$D:$D,MATCH(B34, PJ!$C:$C, 0))) | G34: 実績 | W34: =SUM(I34:V34) -> 0
A35: 11 | B35: =IF($B36="","",INDEX(PJ!$A:$A,MATCH(B36,PJ!$C:$C,0))) | C35: =IF($B36="","",INDEX(PJ!$B:$B,MATCH(B36, PJ!$C:$C, 0))) | D35: =IF(D36="","",INDEX(工種!$A$2:$A$83,MATCH(D36,工種!$B$2:$B$83,0),1)) | G35: 予定
C36: =IF($B36="","",INDEX(PJ!$D:$D,MATCH(B36, PJ!$C:$C, 0))) | G36: 実績 | W36: =SUM(I36:V36) -> 0
A37: 12 | B37: =IF($B38="","",INDEX(PJ!$A:$A,MATCH(B38,PJ!$C:$C,0))) | C37: =IF($B38="","",INDEX(PJ!$B:$B,MATCH(B38, PJ!$C:$C, 0))) | D37: =IF(D38="","",INDEX(工種!$A$2:$A$83,MATCH(D38,工種!$B$2:$B$83,0),1)) | G37: 予定
C38: =IF($B38="","",INDEX(PJ!$D:$D,MATCH(B38, PJ!$C:$C, 0))) | G38: 実績 | W38: =SUM(I38:V38) -> 0
A39: 13 | B39: =IF($B40="","",INDEX(PJ!$A:$A,MATCH(B40,PJ!$C:$C,0))) | C39: =IF($B40="","",INDEX(PJ!$B:$B,MATCH(B40, PJ!$C:$C, 0))) | D39: =IF(D40="","",INDEX(工種!$A$2:$A$83,MATCH(D40,工種!$B$2:$B$83,0),1)) | G39: 予定
C40: =IF($B40="","",INDEX(PJ!$D:$D,MATCH(B40, PJ!$C:$C, 0))) | G40: 実績 | W40: =SUM(I40:V40) -> 0
A41: 14 | B41: =IF($B42="","",INDEX(PJ!$A:$A,MATCH(B42,PJ!$C:$C,0))) | C41: =IF($B42="","",INDEX(PJ!$B:$B,MATCH(B42, PJ!$C:$C, 0))) | D41: =IF(D42="","",INDEX(工種!$A$2:$A$83,MATCH(D42,工種!$B$2:$B$83,0),1)) | G41: 予定
C42: =IF($B42="","",INDEX(PJ!$D:$D,MATCH(B42, PJ!$C:$C, 0))) | G42: 実績 | W42: =SUM(I42:V42) -> 0
...

Sheet 4週
A1: 週間進捗状況報告書
T2: 管理者 | W2: 本人
B3: ='1週'!B3 -> 2026 | C3: ='1週'!C3 -> 7
C4: =IF('1週'!C3="","",IF('1週'!C4=1,4,3)) -> 4
B6: 会社名 | C6: ='1週'!C6 -> FPTジャパン
B7: 氏名 | C7: ='1週'!C7 -> LE NHUT THIEN
I8: 月 | K8: 火 | M8: 水 | O8: 木 | Q8: 金 | S8: 土 | U8: 日
I9: ='3週'!U9+1 -> 20 | K9: =I9+1 -> 21 | M9: =K9+1 -> 22 | O9: =M9+1 -> 23 | Q9: =O9+1 -> 24 | S9: =Q9+1 -> 25 | U9: =S9+1 -> 26
A10: No | B10: システムコード | C10: システム名 | D10: 工種コード | E10: 主な作業内容（予定） | F10: 予定 | G10: 始業 | K10: 0.375 | M10: 0.375 | O10: 0.375 | Q10: 0.375 | W10: 累計
B11: プロジェクトコード | C11: プロジェクト名 | D11: 工種 | F11: 達成度 | G11: 終業 | K11: 0.77083333 | M11: 0.77083333 | O11: 0.77083333 | Q11: 0.77083333 | W11: ='3週'!W11+W13 -> 7.5
F12: 休憩・外出時間 | K12: 0.041666667 | M12: 0.041666667 | O12: 0.041666667 | Q12: 0.041666667 | W12: 合計
A13: 合計 | I13: =TIMEVALUE(TEXT(I11-I10-I12,"h:mm:ss")) -> 0.375 | K13: =TIMEVALUE(TEXT(K11-K10-K12,"h:mm:ss")) -> 0.375 | M13: =TIMEVALUE(TEXT(M11-M10-M12,"h:mm:ss")) -> 0.375 | O13: =TIMEVALUE(TEXT(O11-O10-O12,"h:mm:ss")) -> 0.375 | Q13: =TIMEVALUE(TEXT(Q11-Q10-Q12,"h:mm:ss")) -> 0.375 | S13: =TIMEVALUE(TEXT(S11-S10-S12,"h:mm:ss")) -> 0 | U13: =TIMEVALUE(TEXT(U11-U10-U12,"h:mm:ss")) -> 0 | W13: =CEILING(SUM(I13:V13),"0:5") -> 1.875
A15: 1 | B15: =IF($B16="","",INDEX(PJ!$A:$A,MATCH(B16,PJ!$C:$C,0))) -> 10000 | C15: =IF($B16="","",INDEX(PJ!$B:$B,MATCH(B16, PJ!$C:$C, 0))) -> Yokogawa | D15: =IF(D16="","",INDEX(工種!$A$2:$A$83,MATCH(D16,工種!$B$2:$B$83,0),1)) -> 10102 | G15: 予定
B16: 10000 | C16: =IF($B16="","",INDEX(PJ!$D:$D,MATCH(B16, PJ!$C:$C, 0))) -> Rep Portal | D16: 製造：コーディング | E16: コーディング | G16: 実績 | K16: 0.27083333 | M16: 0.27083333 | O16: 0.27083333 | Q16: 0.27083333 | W16: =SUM(I16:V16) -> 1.0416667
A17: 2 | B17: =IF($B18="","",INDEX(PJ!$A:$A,MATCH(B18,PJ!$C:$C,0))) -> 10000 | C17: =IF($B18="","",INDEX(PJ!$B:$B,MATCH(B18, PJ!$C:$C, 0))) -> Yokogawa | D17: =IF(D18="","",INDEX(工種!$A$2:$A$83,MATCH(D18,工種!$B$2:$B$83,0),1)) -> 30106 | G17: 予定
B18: 10000 | C18: =IF($B18="","",INDEX(PJ!$D:$D,MATCH(B18, PJ!$C:$C, 0))) -> Rep Portal | D18: テスト：結合テスト実施 | E18: 結合テスト実施 | G18: 実績 | K18: 0.083333333 | M18: 0.083333333 | O18: 0.083333333 | Q18: 0.083333333 | W18: =SUM(I18:V18) -> 0.625
A19: 3 | B19: =IF($B20="","",INDEX(PJ!$A:$A,MATCH(B20,PJ!$C:$C,0))) -> 10000 | C19: =IF($B20="","",INDEX(PJ!$B:$B,MATCH(B20, PJ!$C:$C, 0))) -> Yokogawa | D19: =IF(D20="","",INDEX(工種!$A$2:$A$83,MATCH(D20,工種!$B$2:$B$83,0),1)) -> 40108 | G19: 予定
C20: =IF($B20="","",INDEX(PJ!$D:$D,MATCH(B20, PJ!$C:$C, 0))) -> Rep Portal | G20: 実績 | W20: =SUM(I20:V20) -> 0.52083333
A21: 4 | B21: =IF($B22="","",INDEX(PJ!$A:$A,MATCH(B22,PJ!$C:$C,0))) | C21: =IF($B22="","",INDEX(PJ!$B:$B,MATCH(B22, PJ!$C:$C, 0))) | D21: =IF(D22="","",INDEX(工種!$A$2:$A$83,MATCH(D22,工種!$B$2:$B$83,0),1)) | G21: 予定
C22: =IF($B22="","",INDEX(PJ!$D:$D,MATCH(B22, PJ!$C:$C, 0))) | G22: 実績 | W22: =SUM(I22:V22) -> 0
A23: 5 | B23: =IF($B24="","",INDEX(PJ!$A:$A,MATCH(B24,PJ!$C:$C,0))) | C23: =IF($B24="","",INDEX(PJ!$B:$B,MATCH(B24, PJ!$C:$C, 0))) | D23: =IF(D24="","",INDEX(工種!$A$2:$A$83,MATCH(D24,工種!$B$2:$B$83,0),1)) | G23: 予定
C24: =IF($B24="","",INDEX(PJ!$D:$D,MATCH(B24, PJ!$C:$C, 0))) | G24: 実績 | W24: =SUM(I24:V24) -> 0
A25: 6 | B25: =IF($B26="","",INDEX(PJ!$A:$A,MATCH(B26,PJ!$C:$C,0))) | C25: =IF($B26="","",INDEX(PJ!$B:$B,MATCH(B26, PJ!$C:$C, 0))) | D25: =IF(D26="","",INDEX(工種!$A$2:$A$83,MATCH(D26,工種!$B$2:$B$83,0),1)) | G25: 予定
C26: =IF($B26="","",INDEX(PJ!$D:$D,MATCH(B26, PJ!$C:$C, 0))) | G26: 実績 | W26: =SUM(I26:V26) -> 0
A27: 7 | B27: =IF($B28="","",INDEX(PJ!$A:$A,MATCH(B28,PJ!$C:$C,0))) | C27: =IF($B28="","",INDEX(PJ!$B:$B,MATCH(B28, PJ!$C:$C, 0))) | D27: =IF(D28="","",INDEX(工種!$A$2:$A$83,MATCH(D28,工種!$B$2:$B$83,0),1)) | G27: 予定
C28: =IF($B28="","",INDEX(PJ!$D:$D,MATCH(B28, PJ!$C:$C, 0))) | G28: 実績 | W28: =SUM(I28:V28) -> 0
A29: 8 | B29: =IF($B30="","",INDEX(PJ!$A:$A,MATCH(B30,PJ!$C:$C,0))) | C29: =IF($B30="","",INDEX(PJ!$B:$B,MATCH(B30, PJ!$C:$C, 0))) | D29: =IF(D30="","",INDEX(工種!$A$2:$A$83,MATCH(D30,工種!$B$2:$B$83,0),1)) | G29: 予定
C30: =IF($B30="","",INDEX(PJ!$D:$D,MATCH(B30, PJ!$C:$C, 0))) | G30: 実績 | W30: =SUM(I30:V30) -> 0
A31: 9 | B31: =IF($B32="","",INDEX(PJ!$A:$A,MATCH(B32,PJ!$C:$C,0))) | C31: =IF($B32="","",INDEX(PJ!$B:$B,MATCH(B32, PJ!$C:$C, 0))) | D31: =IF(D32="","",INDEX(工種!$A$2:$A$83,MATCH(D32,工種!$B$2:$B$83,0),1)) | G31: 予定
C32: =IF($B32="","",INDEX(PJ!$D:$D,MATCH(B32, PJ!$C:$C, 0))) | G32: 実績 | W32: =SUM(I32:V32) -> 0
A33: 10 | B33: =IF($B34="","",INDEX(PJ!$A:$A,MATCH(B34,PJ!$C:$C,0))) | C33: =IF($B34="","",INDEX(PJ!$B:$B,MATCH(B34, PJ!$C:$C, 0))) | D33: =IF(D34="","",INDEX(工種!$A$2:$A$83,MATCH(D34,工種!$B$2:$B$83,0),1)) | G33: 予定
C34: =IF($B34="","",INDEX(PJ!$D:$D,MATCH(B34, PJ!$C:$C, 0))) | G34: 実績 | W34: =SUM(I34:V34) -> 0
A35: 11 | B35: =IF($B36="","",INDEX(PJ!$A:$A,MATCH(B36,PJ!$C:$C,0))) | C35: =IF($B36="","",INDEX(PJ!$B:$B,MATCH(B36, PJ!$C:$C, 0))) | D35: =IF(D36="","",INDEX(工種!$A$2:$A$83,MATCH(D36,工種!$B$2:$B$83,0),1)) | G35: 予定
C36: =IF($B36="","",INDEX(PJ!$D:$D,MATCH(B36, PJ!$C:$C, 0))) | G36: 実績 | W36: =SUM(I36:V36) -> 0
A37: 12 | B37: =IF($B38="","",INDEX(PJ!$A:$A,MATCH(B38,PJ!$C:$C,0))) | C37: =IF($B38="","",INDEX(PJ!$B:$B,MATCH(B38, PJ!$C:$C, 0))) | D37: =IF(D38="","",INDEX(工種!$A$2:$A$83,MATCH(D38,工種!$B$2:$B$83,0),1)) | G37: 予定
C38: =IF($B38="","",INDEX(PJ!$D:$D,MATCH(B38, PJ!$C:$C, 0))) | G38: 実績 | W38: =SUM(I38:V38) -> 0
A39: 13 | B39: =IF($B40="","",INDEX(PJ!$A:$A,MATCH(B40,PJ!$C:$C,0))) | C39: =IF($B40="","",INDEX(PJ!$B:$B,MATCH(B40, PJ!$C:$C, 0))) | D39: =IF(D40="","",INDEX(工種!$A$2:$A$83,MATCH(D40,工種!$B$2:$B$83,0),1)) | G39: 予定
C40: =IF($B40="","",INDEX(PJ!$D:$D,MATCH(B40, PJ!$C:$C, 0))) | G40: 実績 | W40: =SUM(I40:V40) -> 0
A41: 14 | B41: =IF($B42="","",INDEX(PJ!$A:$A,MATCH(B42,PJ!$C:$C,0))) | C41: =IF($B42="","",INDEX(PJ!$B:$B,MATCH(B42, PJ!$C:$C, 0))) | D41: =IF(D42="","",INDEX(工種!$A$2:$A$83,MATCH(D42,工種!$B$2:$B$83,0),1)) | G41: 予定
C42: =IF($B42="","",INDEX(PJ!$D:$D,MATCH(B42, PJ!$C:$C, 0))) | G42: 実績 | W42: =SUM(I42:V42) -> 0
...

Sheet 5週
A1: 週間進捗状況報告書
T2: 管理者 | W2: 本人
B3: ='1週'!B3 -> 2026 | C3: ='1週'!C3 -> 7
C4: =IF('1週'!C3="","",IF('1週'!C4=1,5,4)) -> 5
B6: 会社名 | C6: ='1週'!C6 -> FPTジャパン
B7: 氏名 | C7: ='1週'!C7 -> LE NHUT THIEN
I8: 月 | K8: 火 | M8: 水 | O8: 木 | Q8: 金 | S8: 土 | U8: 日
I9: =IF(ISERR(WEEKDAY($B$3&"/"&$C$3&"/"&'4週'!U9+1))=TRUE,"",'4週'!U9+1) -> 27 | K9: =IF(ISERR(WEEKDAY($B$3&"/"&$C$3&"/"&I9+1))=TRUE,"",I9+1) -> 28 | M9: =IF(ISERR(WEEKDAY($B$3&"/"&$C$3&"/"&K9+1))=TRUE,"",K9+1) -> 29 | O9: =IF(ISERR(WEEKDAY($B$3&"/"&$C$3&"/"&M9+1))=TRUE,"",M9+1) -> 30 | Q9: =IF(ISERR(WEEKDAY($B$3&"/"&$C$3&"/"&O9+1))=TRUE,"",O9+1) -> 31 | S9: =IF(ISERR(WEEKDAY($B$3&"/"&$C$3&"/"&Q9+1))=TRUE,"",Q9+1) | U9: =IF(ISERR(WEEKDAY($B$3&"/"&$C$3&"/"&S9+1))=TRUE,"",S9+1)
A10: No | B10: システムコード | C10: システム名 | D10: 工種コード | E10: 主な作業内容（予定） | F10: 予定 | G10: 始業 | I10: 0.375 | K10: 0.375 | M10: 0.375 | O10: 0.375 | Q10: 0.375 | W10: 累計
B11: プロジェクトコード | C11: プロジェクト名 | D11: 工種 | F11: 達成度 | G11: 終業 | I11: 0.77083333 | K11: 0.77083333 | M11: 0.77083333 | O11: 0.77083333 | Q11: 0.77083333 | W11: ='4週'!W11+W13 -> 8.25
F12: 休憩・外出時間 | I12: 0.041666667 | K12: 0.041666667 | M12: 0.041666667 | O12: 0.041666667 | Q12: 0.041666667 | W12: 合計
A13: 合計 | I13: =TIMEVALUE(TEXT(I11-I10-I12,"h:mm:ss")) -> 0.375 | K13: =TIMEVALUE(TEXT(K11-K10-K12,"h:mm:ss")) -> 0.375 | M13: =TIMEVALUE(TEXT(M11-M10-M12,"h:mm:ss")) -> 0 | O13: =TIMEVALUE(TEXT(O11-O10-O12,"h:mm:ss")) -> 0 | Q13: =TIMEVALUE(TEXT(Q11-Q10-Q12,"h:mm:ss")) -> 0 | S13: =TIMEVALUE(TEXT(S11-S10-S12,"h:mm:ss")) -> 0 | U13: =TIMEVALUE(TEXT(U11-U10-U12,"h:mm:ss")) -> 0 | W13: =CEILING(SUM(I13:V13),"0:5") -> 0.75
A15: 1 | B15: =IF($B16="","",INDEX(PJ!$A:$A,MATCH(B16,PJ!$C:$C,0))) -> 10000 | C15: =IF($B16="","",INDEX(PJ!$B:$B,MATCH(B16, PJ!$C:$C, 0))) -> Yokogawa | D15: =IF(D16="","",INDEX(工種!$A$2:$A$83,MATCH(D16,工種!$B$2:$B$83,0),1)) -> 10102 | G15: 予定
B16: 10000 | C16: =IF($B16="","",INDEX(PJ!$D:$D,MATCH(B16, PJ!$C:$C, 0))) -> Rep Portal | D16: 製造：コーディング | E16: コーディング | G16: 実績 | I16: 0.27083333 | K16: 0.27083333 | M16: 0.27083333 | O16: 0.22916667 | Q16: 0.27083333 | W16: =SUM(I16:V16) -> 0.83333333
A17: 2 | B17: =IF($B18="","",INDEX(PJ!$A:$A,MATCH(B18,PJ!$C:$C,0))) -> 10000 | C17: =IF($B18="","",INDEX(PJ!$B:$B,MATCH(B18, PJ!$C:$C, 0))) -> Yokogawa | D17: =IF(D18="","",INDEX(工種!$A$2:$A$83,MATCH(D18,工種!$B$2:$B$83,0),1)) -> 30106 | G17: 予定
B18: 10000 | C18: =IF($B18="","",INDEX(PJ!$D:$D,MATCH(B18, PJ!$C:$C, 0))) -> Rep Portal | D18: テスト：結合テスト実施 | E18: 結合テスト実施 | G18: 実績 | I18: 0.083333333 | K18: 0.083333333 | M18: 0.083333333 | O18: 0.083333333 | Q18: 0.083333333 | W18: =SUM(I18:V18) -> 0.5
A19: 3 | B19: =IF($B20="","",INDEX(PJ!$A:$A,MATCH(B20,PJ!$C:$C,0))) -> 10000 | C19: =IF($B20="","",INDEX(PJ!$B:$B,MATCH(B20, PJ!$C:$C, 0))) -> Yokogawa | D19: =IF(D20="","",INDEX(工種!$A$2:$A$83,MATCH(D20,工種!$B$2:$B$83,0),1)) -> 40108 | G19: 予定
B20: 10000 | C20: =IF($B20="","",INDEX(PJ!$D:$D,MATCH(B20, PJ!$C:$C, 0))) -> Rep Portal | D20: 管理業務：打合せ | E20: 打合せ | G20: 実績 | O20: 0.041666667 | W20: =SUM(I20:V20) -> 0.41666667
A21: 4 | B21: =IF($B22="","",INDEX(PJ!$A:$A,MATCH(B22,PJ!$C:$C,0))) | C21: =IF($B22="","",INDEX(PJ!$B:$B,MATCH(B22, PJ!$C:$C, 0))) | D21: =IF(D22="","",INDEX(工種!$A$2:$A$83,MATCH(D22,工種!$B$2:$B$83,0),1)) | G21: 予定
C22: =IF($B22="","",INDEX(PJ!$D:$D,MATCH(B22, PJ!$C:$C, 0))) | G22: 実績 | W22: =SUM(I22:V22) -> 0
A23: 5 | B23: =IF($B24="","",INDEX(PJ!$A:$A,MATCH(B24,PJ!$C:$C,0))) | C23: =IF($B24="","",INDEX(PJ!$B:$B,MATCH(B24, PJ!$C:$C, 0))) | D23: =IF(D24="","",INDEX(工種!$A$2:$A$83,MATCH(D24,工種!$B$2:$B$83,0),1)) | G23: 予定
C24: =IF($B24="","",INDEX(PJ!$D:$D,MATCH(B24, PJ!$C:$C, 0))) | G24: 実績 | W24: =SUM(I24:V24) -> 0
A25: 6 | B25: =IF($B26="","",INDEX(PJ!$A:$A,MATCH(B26,PJ!$C:$C,0))) | C25: =IF($B26="","",INDEX(PJ!$B:$B,MATCH(B26, PJ!$C:$C, 0))) | D25: =IF(D26="","",INDEX(工種!$A$2:$A$83,MATCH(D26,工種!$B$2:$B$83,0),1)) | G25: 予定
C26: =IF($B26="","",INDEX(PJ!$D:$D,MATCH(B26, PJ!$C:$C, 0))) | G26: 実績 | W26: =SUM(I26:V26) -> 0
A27: 7 | B27: =IF($B28="","",INDEX(PJ!$A:$A,MATCH(B28,PJ!$C:$C,0))) | C27: =IF($B28="","",INDEX(PJ!$B:$B,MATCH(B28, PJ!$C:$C, 0))) | D27: =IF(D28="","",INDEX(工種!$A$2:$A$83,MATCH(D28,工種!$B$2:$B$83,0),1)) | G27: 予定
C28: =IF($B28="","",INDEX(PJ!$D:$D,MATCH(B28, PJ!$C:$C, 0))) | G28: 実績 | W28: =SUM(I28:V28) -> 0
A29: 8 | B29: =IF($B30="","",INDEX(PJ!$A:$A,MATCH(B30,PJ!$C:$C,0))) | C29: =IF($B30="","",INDEX(PJ!$B:$B,MATCH(B30, PJ!$C:$C, 0))) | D29: =IF(D30="","",INDEX(工種!$A$2:$A$83,MATCH(D30,工種!$B$2:$B$83,0),1)) | G29: 予定
C30: =IF($B30="","",INDEX(PJ!$D:$D,MATCH(B30, PJ!$C:$C, 0))) | G30: 実績 | W30: =SUM(I30:V30) -> 0
A31: 9 | B31: =IF($B32="","",INDEX(PJ!$A:$A,MATCH(B32,PJ!$C:$C,0))) | C31: =IF($B32="","",INDEX(PJ!$B:$B,MATCH(B32, PJ!$C:$C, 0))) | D31: =IF(D32="","",INDEX(工種!$A$2:$A$83,MATCH(D32,工種!$B$2:$B$83,0),1)) | G31: 予定
C32: =IF($B32="","",INDEX(PJ!$D:$D,MATCH(B32, PJ!$C:$C, 0))) | G32: 実績 | W32: =SUM(I32:V32) -> 0
A33: 10 | B33: =IF($B34="","",INDEX(PJ!$A:$A,MATCH(B34,PJ!$C:$C,0))) | C33: =IF($B34="","",INDEX(PJ!$B:$B,MATCH(B34, PJ!$C:$C, 0))) | D33: =IF(D34="","",INDEX(工種!$A$2:$A$83,MATCH(D34,工種!$B$2:$B$83,0),1)) | G33: 予定
C34: =IF($B34="","",INDEX(PJ!$D:$D,MATCH(B34, PJ!$C:$C, 0))) | G34: 実績 | W34: =SUM(I34:V34) -> 0
A35: 11 | B35: =IF($B36="","",INDEX(PJ!$A:$A,MATCH(B36,PJ!$C:$C,0))) | C35: =IF($B36="","",INDEX(PJ!$B:$B,MATCH(B36, PJ!$C:$C, 0))) | D35: =IF(D36="","",INDEX(工種!$A$2:$A$83,MATCH(D36,工種!$B$2:$B$83,0),1)) | G35: 予定
C36: =IF($B36="","",INDEX(PJ!$D:$D,MATCH(B36, PJ!$C:$C, 0))) | G36: 実績 | W36: =SUM(I36:V36) -> 0
A37: 12 | B37: =IF($B38="","",INDEX(PJ!$A:$A,MATCH(B38,PJ!$C:$C,0))) | C37: =IF($B38="","",INDEX(PJ!$B:$B,MATCH(B38, PJ!$C:$C, 0))) | D37: =IF(D38="","",INDEX(工種!$A$2:$A$83,MATCH(D38,工種!$B$2:$B$83,0),1)) | G37: 予定
C38: =IF($B38="","",INDEX(PJ!$D:$D,MATCH(B38, PJ!$C:$C, 0))) | G38: 実績 | W38: =SUM(I38:V38) -> 0
A39: 13 | B39: =IF($B40="","",INDEX(PJ!$A:$A,MATCH(B40,PJ!$C:$C,0))) | C39: =IF($B40="","",INDEX(PJ!$B:$B,MATCH(B40, PJ!$C:$C, 0))) | D39: =IF(D40="","",INDEX(工種!$A$2:$A$83,MATCH(D40,工種!$B$2:$B$83,0),1)) | G39: 予定
C40: =IF($B40="","",INDEX(PJ!$D:$D,MATCH(B40, PJ!$C:$C, 0))) | G40: 実績 | W40: =SUM(I40:V40) -> 0
A41: 14 | B41: =IF($B42="","",INDEX(PJ!$A:$A,MATCH(B42,PJ!$C:$C,0))) | C41: =IF($B42="","",INDEX(PJ!$B:$B,MATCH(B42, PJ!$C:$C, 0))) | D41: =IF(D42="","",INDEX(工種!$A$2:$A$83,MATCH(D42,工種!$B$2:$B$83,0),1)) | G41: 予定
C42: =IF($B42="","",INDEX(PJ!$D:$D,MATCH(B42, PJ!$C:$C, 0))) | G42: 実績 | W42: =SUM(I42:V42) -> 0
...

Sheet 6週
A1: 週間進捗状況報告書
T2: 管理者 | W2: 本人
B3: ='1週'!B3 -> 2026 | C3: ='1週'!C3 -> 7
C4: =IF(I9="","",IF('1週'!C4=1,6,5))
B6: 会社名 | C6: ='1週'!C6 -> FPTジャパン
B7: 氏名 | C7: ='1週'!C7 -> LE NHUT THIEN
I8: 月 | K8: 火 | M8: 水 | O8: 木 | Q8: 金 | S8: 土 | U8: 日
I9: =IF(ISERR(WEEKDAY($B$3&"/"&$C$3&"/"&'5週'!U9+1))=TRUE,"",'5週'!U9+1) | K9: =IF(ISERR(WEEKDAY($B$3&"/"&$C$3&"/"&I9+1))=TRUE,"",I9+1) | M9: =IF(ISERR(WEEKDAY($B$3&"/"&$C$3&"/"&K9+1))=TRUE,"",K9+1) | O9: =IF(ISERR(WEEKDAY($B$3&"/"&$C$3&"/"&M9+1))=TRUE,"",M9+1) | Q9: =IF(ISERR(WEEKDAY($B$3&"/"&$C$3&"/"&O9+1))=TRUE,"",O9+1) | S9: =IF(ISERR(WEEKDAY($B$3&"/"&$C$3&"/"&Q9+1))=TRUE,"",Q9+1) | U9: =IF(ISERR(WEEKDAY($B$3&"/"&$C$3&"/"&S9+1))=TRUE,"",S9+1)
A10: No | B10: システムコード | C10: システム名 | D10: 工種コード | E10: 主な作業内容（予定） | F10: 予定 | G10: 始業 | W10: 累計
B11: プロジェクトコード | C11: プロジェクト名 | D11: 工種 | F11: 達成度 | G11: 終業 | W11: ='5週'!W11+W13 -> 8.25
F12: 休憩・外出時間 | W12: 合計
A13: 合計 | I13: =TIMEVALUE(TEXT(I11-I10-I12,"h:mm:ss")) -> 0 | K13: =TIMEVALUE(TEXT(K11-K10-K12,"h:mm:ss")) -> 0 | M13: =TIMEVALUE(TEXT(M11-M10-M12,"h:mm:ss")) -> 0 | O13: =TIMEVALUE(TEXT(O11-O10-O12,"h:mm:ss")) -> 0 | Q13: =TIMEVALUE(TEXT(Q11-Q10-Q12,"h:mm:ss")) -> 0 | S13: =TIMEVALUE(TEXT(S11-S10-S12,"h:mm:ss")) -> 0 | U13: =TIMEVALUE(TEXT(U11-U10-U12,"h:mm:ss")) -> 0 | W13: =CEILING(SUM(I13:V13),"0:5") -> 0
A15: 1 | B15: =IF($B16="","",INDEX(PJ!$A:$A,MATCH(B16,PJ!$C:$C,0))) -> 10000 | C15: =IF($B16="","",INDEX(PJ!$B:$B,MATCH(B16, PJ!$C:$C, 0))) -> Yokogawa | D15: =IF(D16="","",INDEX(工種!$A$2:$A$83,MATCH(D16,工種!$B$2:$B$83,0),1)) -> 10102 | G15: 予定
C16: =IF($B16="","",INDEX(PJ!$D:$D,MATCH(B16, PJ!$C:$C, 0))) -> Rep Portal | G16: 実績 | W16: =SUM(I16:V16) -> 0
A17: 2 | B17: =IF($B18="","",INDEX(PJ!$A:$A,MATCH(B18,PJ!$C:$C,0))) -> 10000 | C17: =IF($B18="","",INDEX(PJ!$B:$B,MATCH(B18, PJ!$C:$C, 0))) -> Yokogawa | D17: =IF(D18="","",INDEX(工種!$A$2:$A$83,MATCH(D18,工種!$B$2:$B$83,0),1)) -> 30106 | G17: 予定
C18: =IF($B18="","",INDEX(PJ!$D:$D,MATCH(B18, PJ!$C:$C, 0))) -> Rep Portal | G18: 実績 | W18: =SUM(I18:V18) -> 0
A19: 3 | B19: =IF($B20="","",INDEX(PJ!$A:$A,MATCH(B20,PJ!$C:$C,0))) -> 10000 | C19: =IF($B20="","",INDEX(PJ!$B:$B,MATCH(B20, PJ!$C:$C, 0))) -> Yokogawa | D19: =IF(D20="","",INDEX(工種!$A$2:$A$83,MATCH(D20,工種!$B$2:$B$83,0),1)) -> 40108 | G19: 予定
C20: =IF($B20="","",INDEX(PJ!$D:$D,MATCH(B20, PJ!$C:$C, 0))) -> Rep Portal | G20: 実績 | W20: =SUM(I20:V20) -> 0
A21: 4 | B21: =IF($B22="","",INDEX(PJ!$A:$A,MATCH(B22,PJ!$C:$C,0))) | C21: =IF($B22="","",INDEX(PJ!$B:$B,MATCH(B22, PJ!$C:$C, 0))) | D21: =IF(D22="","",INDEX(工種!$A$2:$A$83,MATCH(D22,工種!$B$2:$B$83,0),1)) | G21: 予定
C22: =IF($B22="","",INDEX(PJ!$D:$D,MATCH(B22, PJ!$C:$C, 0))) | G22: 実績 | W22: =SUM(I22:V22) -> 0
A23: 5 | B23: =IF($B24="","",INDEX(PJ!$A:$A,MATCH(B24,PJ!$C:$C,0))) | C23: =IF($B24="","",INDEX(PJ!$B:$B,MATCH(B24, PJ!$C:$C, 0))) | D23: =IF(D24="","",INDEX(工種!$A$2:$A$83,MATCH(D24,工種!$B$2:$B$83,0),1)) | G23: 予定
C24: =IF($B24="","",INDEX(PJ!$D:$D,MATCH(B24, PJ!$C:$C, 0))) | G24: 実績 | W24: =SUM(I24:V24) -> 0
A25: 6 | B25: =IF($B26="","",INDEX(PJ!$A:$A,MATCH(B26,PJ!$C:$C,0))) | C25: =IF($B26="","",INDEX(PJ!$B:$B,MATCH(B26, PJ!$C:$C, 0))) | D25: =IF(D26="","",INDEX(工種!$A$2:$A$83,MATCH(D26,工種!$B$2:$B$83,0),1)) | G25: 予定
C26: =IF($B26="","",INDEX(PJ!$D:$D,MATCH(B26, PJ!$C:$C, 0))) | G26: 実績 | W26: =SUM(I26:V26) -> 0
A27: 7 | B27: =IF($B28="","",INDEX(PJ!$A:$A,MATCH(B28,PJ!$C:$C,0))) | C27: =IF($B28="","",INDEX(PJ!$B:$B,MATCH(B28, PJ!$C:$C, 0))) | D27: =IF(D28="","",INDEX(工種!$A$2:$A$83,MATCH(D28,工種!$B$2:$B$83,0),1)) | G27: 予定
C28: =IF($B28="","",INDEX(PJ!$D:$D,MATCH(B28, PJ!$C:$C, 0))) | G28: 実績 | W28: =SUM(I28:V28) -> 0
A29: 8 | B29: =IF($B30="","",INDEX(PJ!$A:$A,MATCH(B30,PJ!$C:$C,0))) | C29: =IF($B30="","",INDEX(PJ!$B:$B,MATCH(B30, PJ!$C:$C, 0))) | D29: =IF(D30="","",INDEX(工種!$A$2:$A$83,MATCH(D30,工種!$B$2:$B$83,0),1)) | G29: 予定
C30: =IF($B30="","",INDEX(PJ!$D:$D,MATCH(B30, PJ!$C:$C, 0))) | G30: 実績 | W30: =SUM(I30:V30) -> 0
A31: 9 | B31: =IF($B32="","",INDEX(PJ!$A:$A,MATCH(B32,PJ!$C:$C,0))) | C31: =IF($B32="","",INDEX(PJ!$B:$B,MATCH(B32, PJ!$C:$C, 0))) | D31: =IF(D32="","",INDEX(工種!$A$2:$A$83,MATCH(D32,工種!$B$2:$B$83,0),1)) | G31: 予定
C32: =IF($B32="","",INDEX(PJ!$D:$D,MATCH(B32, PJ!$C:$C, 0))) | G32: 実績 | W32: =SUM(I32:V32) -> 0
A33: 10 | B33: =IF($B34="","",INDEX(PJ!$A:$A,MATCH(B34,PJ!$C:$C,0))) | C33: =IF($B34="","",INDEX(PJ!$B:$B,MATCH(B34, PJ!$C:$C, 0))) | D33: =IF(D34="","",INDEX(工種!$A$2:$A$83,MATCH(D34,工種!$B$2:$B$83,0),1)) | G33: 予定
C34: =IF($B34="","",INDEX(PJ!$D:$D,MATCH(B34, PJ!$C:$C, 0))) | G34: 実績 | W34: =SUM(I34:V34) -> 0
A35: 11 | B35: =IF($B36="","",INDEX(PJ!$A:$A,MATCH(B36,PJ!$C:$C,0))) | C35: =IF($B36="","",INDEX(PJ!$B:$B,MATCH(B36, PJ!$C:$C, 0))) | D35: =IF(D36="","",INDEX(工種!$A$2:$A$83,MATCH(D36,工種!$B$2:$B$83,0),1)) | G35: 予定
C36: =IF($B36="","",INDEX(PJ!$D:$D,MATCH(B36, PJ!$C:$C, 0))) | G36: 実績 | W36: =SUM(I36:V36) -> 0
A37: 12 | B37: =IF($B38="","",INDEX(PJ!$A:$A,MATCH(B38,PJ!$C:$C,0))) | C37: =IF($B38="","",INDEX(PJ!$B:$B,MATCH(B38, PJ!$C:$C, 0))) | D37: =IF(D38="","",INDEX(工種!$A$2:$A$83,MATCH(D38,工種!$B$2:$B$83,0),1)) | G37: 予定
C38: =IF($B38="","",INDEX(PJ!$D:$D,MATCH(B38, PJ!$C:$C, 0))) | G38: 実績 | W38: =SUM(I38:V38) -> 0
A39: 13 | B39: =IF($B40="","",INDEX(PJ!$A:$A,MATCH(B40,PJ!$C:$C,0))) | C39: =IF($B40="","",INDEX(PJ!$B:$B,MATCH(B40, PJ!$C:$C, 0))) | D39: =IF(D40="","",INDEX(工種!$A$2:$A$83,MATCH(D40,工種!$B$2:$B$83,0),1)) | G39: 予定
C40: =IF($B40="","",INDEX(PJ!$D:$D,MATCH(B40, PJ!$C:$C, 0))) | G40: 実績 | W40: =SUM(I40:V40) -> 0
A41: 14 | B41: =IF($B42="","",INDEX(PJ!$A:$A,MATCH(B42,PJ!$C:$C,0))) | C41: =IF($B42="","",INDEX(PJ!$B:$B,MATCH(B42, PJ!$C:$C, 0))) | D41: =IF(D42="","",INDEX(工種!$A$2:$A$83,MATCH(D42,工種!$B$2:$B$83,0),1)) | G41: 予定
C42: =IF($B42="","",INDEX(PJ!$D:$D,MATCH(B42, PJ!$C:$C, 0))) | G42: 実績 | W42: =SUM(I42:V42) -> 0
...

Sheet 勤務報告書
G1: =月間集計シート!AI2 -> 2026 | H1: 年 | I1: =月間集計シート!AJ2 -> 7 | J1: 月度 勤務報告書
B3: 就業先 | C3: 会社名 | F3: 横河ソリューションサービス株式会社
C4: 組織単位 | F4: SI 開発部
C5: 就業場所 | F5: 〒105-0011東京都港区芝公園1丁目7-6 | M5: 社名 | N5: =(月間集計シート!$B$29) -> FPTジャパン
B6: 就業した業務 | F6: YOKO Portal 開発 | M6: 氏名 | N6: =(月間集計シート!$C$29)
B8: 日付 | C8: 曜日 | D8: ﾀｲﾌﾟ | E8: 休日 | F8: 休暇 | G8: 出勤時間 | H8: 退勤時間 | I8: 拘束時間 | J8: 休憩－ | K8: 遅早＋ | L8: 就業時間 | M8: 内深夜 | N8: 備 考 | R8: 検印 | T8: 西暦 | U8: 公休
B9: =DATE(T9,I1,1) -> 46204 | C9: =IF(B9<>"",WEEKDAY(B9),"") -> 4 | E9: =IF(U9<>"",U9,IF(C9=1,"公休",IF(C9=7,"公休",""))) | G9: =IF(VLOOKUP($B9,月間集計シート!$AI:$AN,3,FALSE)<>0,VLOOKUP($B9,月間集計シート!$AI:$AN,3,FALSE),"") -> 0.375 | H9: =IF(VLOOKUP($B9,月間集計シート!$AI:$AN,4,FALSE)<>0,VLOOKUP($B9,月間集計シート!$AI:$AN,4,FALSE),"") -> 0.79166667 | I9: =IF(G9="","",IF(H9="","",IF(HOUR(G9)+MINUTE(G9)/60<HOUR(H9)+MINUTE(H9)/60,(HOUR(H9)+MINUTE(H9)/60)-(HOUR(G9)+MINUTE(G9)/60),24-(HOUR(G9)+MINUTE(G9)/60)+(HOUR(H9)+MINUTE(H9)/60)))) -> 10 | J9: =IF(VLOOKUP($B9,月間集計シート!$AI:$AN,5,FALSE)<>0,VLOOKUP($B9,月間集計シート!$AI:$AN,5,FALSE)*24,"") -> 1 | L9: =IF(I9="","",IF(I9>=J9,I9-J9,I9)) -> 9 | T9: =月間集計シート!AI2 -> 2026
B10: =B9+1 -> 46205 | C10: =IF(B10<>"",WEEKDAY(B10),"") -> 5 | E10: =IF(U10<>"",U10,IF(C10=1,"公休",IF(C10=7,"公休",""))) | G10: =IF(VLOOKUP($B10,月間集計シート!$AI:$AN,3,FALSE)<>0,VLOOKUP($B10,月間集計シート!$AI:$AN,3,FALSE),"") -> 0.375 | H10: =IF(VLOOKUP($B10,月間集計シート!$AI:$AN,4,FALSE)<>0,VLOOKUP($B10,月間集計シート!$AI:$AN,4,FALSE),"") -> 0.79166667 | I10: =IF(G10="","",IF(H10="","",IF(HOUR(G10)+MINUTE(G10)/60<HOUR(H10)+MINUTE(H10)/60,(HOUR(H10)+MINUTE(H10)/60)-(HOUR(G10)+MINUTE(G10)/60),24-(HOUR(G10)+MINUTE(G10)/60)+(HOUR(H10)+MINUTE(H10)/60)))) -> 10 | J10: =IF(VLOOKUP($B10,月間集計シート!$AI:$AN,5,FALSE)<>0,VLOOKUP($B10,月間集計シート!$AI:$AN,5,FALSE)*24,"") -> 1 | L10: =IF(I10="","",IF(I10>=J10,I10-J10,I10)) -> 9
B11: =B10+1 -> 46206 | C11: =IF(B11<>"",WEEKDAY(B11),"") -> 6 | E11: =IF(U11<>"",U11,IF(C11=1,"公休",IF(C11=7,"公休",""))) | G11: =IF(VLOOKUP($B11,月間集計シート!$AI:$AN,3,FALSE)<>0,VLOOKUP($B11,月間集計シート!$AI:$AN,3,FALSE),"") -> 0.375 | H11: =IF(VLOOKUP($B11,月間集計シート!$AI:$AN,4,FALSE)<>0,VLOOKUP($B11,月間集計シート!$AI:$AN,4,FALSE),"") -> 0.79166667 | I11: =IF(G11="","",IF(H11="","",IF(HOUR(G11)+MINUTE(G11)/60<HOUR(H11)+MINUTE(H11)/60,(HOUR(H11)+MINUTE(H11)/60)-(HOUR(G11)+MINUTE(G11)/60),24-(HOUR(G11)+MINUTE(G11)/60)+(HOUR(H11)+MINUTE(H11)/60)))) -> 10 | J11: =IF(VLOOKUP($B11,月間集計シート!$AI:$AN,5,FALSE)<>0,VLOOKUP($B11,月間集計シート!$AI:$AN,5,FALSE)*24,"") -> 1 | L11: =IF(I11="","",IF(I11>=J11,I11-J11,I11)) -> 9 | N11: リモート
B12: =B11+1 -> 46207 | C12: =IF(B12<>"",WEEKDAY(B12),"") -> 7 | E12: =IF(U12<>"",U12,IF(C12=1,"公休",IF(C12=7,"公休",""))) -> 公休 | G12: =IF(VLOOKUP($B12,月間集計シート!$AI:$AN,3,FALSE)<>0,VLOOKUP($B12,月間集計シート!$AI:$AN,3,FALSE),"") | H12: =IF(VLOOKUP($B12,月間集計シート!$AI:$AN,4,FALSE)<>0,VLOOKUP($B12,月間集計シート!$AI:$AN,4,FALSE),"") | I12: =IF(G12="","",IF(H12="","",IF(HOUR(G12)+MINUTE(G12)/60<HOUR(H12)+MINUTE(H12)/60,(HOUR(H12)+MINUTE(H12)/60)-(HOUR(G12)+MINUTE(G12)/60),24-(HOUR(G12)+MINUTE(G12)/60)+(HOUR(H12)+MINUTE(H12)/60)))) | J12: =IF(VLOOKUP($B12,月間集計シート!$AI:$AN,5,FALSE)<>0,VLOOKUP($B12,月間集計シート!$AI:$AN,5,FALSE)*24,"") | L12: =IF(I12="","",IF(I12>=J12,I12-J12,I12))
B13: =B12+1 -> 46208 | C13: =IF(B13<>"",WEEKDAY(B13),"") -> 1 | E13: =IF(U13<>"",U13,IF(C13=1,"公休",IF(C13=7,"公休",""))) -> 公休 | G13: =IF(VLOOKUP($B13,月間集計シート!$AI:$AN,3,FALSE)<>0,VLOOKUP($B13,月間集計シート!$AI:$AN,3,FALSE),"") | H13: =IF(VLOOKUP($B13,月間集計シート!$AI:$AN,4,FALSE)<>0,VLOOKUP($B13,月間集計シート!$AI:$AN,4,FALSE),"") | I13: =IF(G13="","",IF(H13="","",IF(HOUR(G13)+MINUTE(G13)/60<HOUR(H13)+MINUTE(H13)/60,(HOUR(H13)+MINUTE(H13)/60)-(HOUR(G13)+MINUTE(G13)/60),24-(HOUR(G13)+MINUTE(G13)/60)+(HOUR(H13)+MINUTE(H13)/60)))) | J13: =IF(VLOOKUP($B13,月間集計シート!$AI:$AN,5,FALSE)<>0,VLOOKUP($B13,月間集計シート!$AI:$AN,5,FALSE)*24,"") | L13: =IF(I13="","",IF(I13>=J13,I13-J13,I13))
B14: =B13+1 -> 46209 | C14: =IF(B14<>"",WEEKDAY(B14),"") -> 2 | E14: =IF(U14<>"",U14,IF(C14=1,"公休",IF(C14=7,"公休",""))) | G14: =IF(VLOOKUP($B14,月間集計シート!$AI:$AN,3,FALSE)<>0,VLOOKUP($B14,月間集計シート!$AI:$AN,3,FALSE),"") -> 0.375 | H14: =IF(VLOOKUP($B14,月間集計シート!$AI:$AN,4,FALSE)<>0,VLOOKUP($B14,月間集計シート!$AI:$AN,4,FALSE),"") -> 0.79166667 | I14: =IF(G14="","",IF(H14="","",IF(HOUR(G14)+MINUTE(G14)/60<HOUR(H14)+MINUTE(H14)/60,(HOUR(H14)+MINUTE(H14)/60)-(HOUR(G14)+MINUTE(G14)/60),24-(HOUR(G14)+MINUTE(G14)/60)+(HOUR(H14)+MINUTE(H14)/60)))) -> 10 | J14: =IF(VLOOKUP($B14,月間集計シート!$AI:$AN,5,FALSE)<>0,VLOOKUP($B14,月間集計シート!$AI:$AN,5,FALSE)*24,"") -> 1 | L14: =IF(I14="","",IF(I14>=J14,I14-J14,I14)) -> 9
B15: =B14+1 -> 46210 | C15: =IF(B15<>"",WEEKDAY(B15),"") -> 3 | E15: =IF(U15<>"",U15,IF(C15=1,"公休",IF(C15=7,"公休",""))) | G15: =IF(VLOOKUP($B15,月間集計シート!$AI:$AN,3,FALSE)<>0,VLOOKUP($B15,月間集計シート!$AI:$AN,3,FALSE),"") -> 0.375 | H15: =IF(VLOOKUP($B15,月間集計シート!$AI:$AN,4,FALSE)<>0,VLOOKUP($B15,月間集計シート!$AI:$AN,4,FALSE),"") -> 0.79166667 | I15: =IF(G15="","",IF(H15="","",IF(HOUR(G15)+MINUTE(G15)/60<HOUR(H15)+MINUTE(H15)/60,(HOUR(H15)+MINUTE(H15)/60)-(HOUR(G15)+MINUTE(G15)/60),24-(HOUR(G15)+MINUTE(G15)/60)+(HOUR(H15)+MINUTE(H15)/60)))) -> 10 | J15: =IF(VLOOKUP($B15,月間集計シート!$AI:$AN,5,FALSE)<>0,VLOOKUP($B15,月間集計シート!$AI:$AN,5,FALSE)*24,"") -> 1 | L15: =IF(I15="","",IF(I15>=J15,I15-J15,I15)) -> 9
B16: =B15+1 -> 46211 | C16: =IF(B16<>"",WEEKDAY(B16),"") -> 4 | E16: =IF(U16<>"",U16,IF(C16=1,"公休",IF(C16=7,"公休",""))) | G16: =IF(VLOOKUP($B16,月間集計シート!$AI:$AN,3,FALSE)<>0,VLOOKUP($B16,月間集計シート!$AI:$AN,3,FALSE),"") -> 0.375 | H16: =IF(VLOOKUP($B16,月間集計シート!$AI:$AN,4,FALSE)<>0,VLOOKUP($B16,月間集計シート!$AI:$AN,4,FALSE),"") -> 0.79166667 | I16: =IF(G16="","",IF(H16="","",IF(HOUR(G16)+MINUTE(G16)/60<HOUR(H16)+MINUTE(H16)/60,(HOUR(H16)+MINUTE(H16)/60)-(HOUR(G16)+MINUTE(G16)/60),24-(HOUR(G16)+MINUTE(G16)/60)+(HOUR(H16)+MINUTE(H16)/60)))) -> 10 | J16: =IF(VLOOKUP($B16,月間集計シート!$AI:$AN,5,FALSE)<>0,VLOOKUP($B16,月間集計シート!$AI:$AN,5,FALSE)*24,"") -> 1 | L16: =IF(I16="","",IF(I16>=J16,I16-J16,I16)) -> 9
B17: =B16+1 -> 46212 | C17: =IF(B17<>"",WEEKDAY(B17),"") -> 5 | E17: =IF(U17<>"",U17,IF(C17=1,"公休",IF(C17=7,"公休",""))) | G17: =IF(VLOOKUP($B17,月間集計シート!$AI:$AN,3,FALSE)<>0,VLOOKUP($B17,月間集計シート!$AI:$AN,3,FALSE),"") -> 0.375 | H17: =IF(VLOOKUP($B17,月間集計シート!$AI:$AN,4,FALSE)<>0,VLOOKUP($B17,月間集計シート!$AI:$AN,4,FALSE),"") -> 0.79166667 | I17: =IF(G17="","",IF(H17="","",IF(HOUR(G17)+MINUTE(G17)/60<HOUR(H17)+MINUTE(H17)/60,(HOUR(H17)+MINUTE(H17)/60)-(HOUR(G17)+MINUTE(G17)/60),24-(HOUR(G17)+MINUTE(G17)/60)+(HOUR(H17)+MINUTE(H17)/60)))) -> 10 | J17: =IF(VLOOKUP($B17,月間集計シート!$AI:$AN,5,FALSE)<>0,VLOOKUP($B17,月間集計シート!$AI:$AN,5,FALSE)*24,"") -> 1 | L17: =IF(I17="","",IF(I17>=J17,I17-J17,I17)) -> 9
B18: =B17+1 -> 46213 | C18: =IF(B18<>"",WEEKDAY(B18),"") -> 6 | E18: =IF(U18<>"",U18,IF(C18=1,"公休",IF(C18=7,"公休",""))) | G18: =IF(VLOOKUP($B18,月間集計シート!$AI:$AN,3,FALSE)<>0,VLOOKUP($B18,月間集計シート!$AI:$AN,3,FALSE),"") -> 0.375 | H18: =IF(VLOOKUP($B18,月間集計シート!$AI:$AN,4,FALSE)<>0,VLOOKUP($B18,月間集計シート!$AI:$AN,4,FALSE),"") -> 0.79166667 | I18: =IF(G18="","",IF(H18="","",IF(HOUR(G18)+MINUTE(G18)/60<HOUR(H18)+MINUTE(H18)/60,(HOUR(H18)+MINUTE(H18)/60)-(HOUR(G18)+MINUTE(G18)/60),24-(HOUR(G18)+MINUTE(G18)/60)+(HOUR(H18)+MINUTE(H18)/60)))) -> 10 | J18: =IF(VLOOKUP($B18,月間集計シート!$AI:$AN,5,FALSE)<>0,VLOOKUP($B18,月間集計シート!$AI:$AN,5,FALSE)*24,"") -> 1 | L18: =IF(I18="","",IF(I18>=J18,I18-J18,I18)) -> 9
B19: =B18+1 -> 46214 | C19: =IF(B19<>"",WEEKDAY(B19),"") -> 7 | E19: =IF(U19<>"",U19,IF(C19=1,"公休",IF(C19=7,"公休",""))) -> 公休 | G19: =IF(VLOOKUP($B19,月間集計シート!$AI:$AN,3,FALSE)<>0,VLOOKUP($B19,月間集計シート!$AI:$AN,3,FALSE),"") | H19: =IF(VLOOKUP($B19,月間集計シート!$AI:$AN,4,FALSE)<>0,VLOOKUP($B19,月間集計シート!$AI:$AN,4,FALSE),"") | I19: =IF(G19="","",IF(H19="","",IF(HOUR(G19)+MINUTE(G19)/60<HOUR(H19)+MINUTE(H19)/60,(HOUR(H19)+MINUTE(H19)/60)-(HOUR(G19)+MINUTE(G19)/60),24-(HOUR(G19)+MINUTE(G19)/60)+(HOUR(H19)+MINUTE(H19)/60)))) | J19: =IF(VLOOKUP($B19,月間集計シート!$AI:$AN,5,FALSE)<>0,VLOOKUP($B19,月間集計シート!$AI:$AN,5,FALSE)*24,"") | L19: =IF(I19="","",IF(I19>=J19,I19-J19,I19))
B20: =B19+1 -> 46215 | C20: =IF(B20<>"",WEEKDAY(B20),"") -> 1 | E20: =IF(U20<>"",U20,IF(C20=1,"公休",IF(C20=7,"公休",""))) -> 公休 | G20: =IF(VLOOKUP($B20,月間集計シート!$AI:$AN,3,FALSE)<>0,VLOOKUP($B20,月間集計シート!$AI:$AN,3,FALSE),"") | H20: =IF(VLOOKUP($B20,月間集計シート!$AI:$AN,4,FALSE)<>0,VLOOKUP($B20,月間集計シート!$AI:$AN,4,FALSE),"") | I20: =IF(G20="","",IF(H20="","",IF(HOUR(G20)+MINUTE(G20)/60<HOUR(H20)+MINUTE(H20)/60,(HOUR(H20)+MINUTE(H20)/60)-(HOUR(G20)+MINUTE(G20)/60),24-(HOUR(G20)+MINUTE(G20)/60)+(HOUR(H20)+MINUTE(H20)/60)))) | J20: =IF(VLOOKUP($B20,月間集計シート!$AI:$AN,5,FALSE)<>0,VLOOKUP($B20,月間集計シート!$AI:$AN,5,FALSE)*24,"") | L20: =IF(I20="","",IF(I20>=J20,I20-J20,I20))
B21: =B20+1 -> 46216 | C21: =IF(B21<>"",WEEKDAY(B21),"") -> 2 | E21: =IF(U21<>"",U21,IF(C21=1,"公休",IF(C21=7,"公休",""))) | G21: =IF(VLOOKUP($B21,月間集計シート!$AI:$AN,3,FALSE)<>0,VLOOKUP($B21,月間集計シート!$AI:$AN,3,FALSE),"") -> 0.375 | H21: =IF(VLOOKUP($B21,月間集計シート!$AI:$AN,4,FALSE)<>0,VLOOKUP($B21,月間集計シート!$AI:$AN,4,FALSE),"") -> 0.79166667 | I21: =IF(G21="","",IF(H21="","",IF(HOUR(G21)+MINUTE(G21)/60<HOUR(H21)+MINUTE(H21)/60,(HOUR(H21)+MINUTE(H21)/60)-(HOUR(G21)+MINUTE(G21)/60),24-(HOUR(G21)+MINUTE(G21)/60)+(HOUR(H21)+MINUTE(H21)/60)))) -> 10 | J21: =IF(VLOOKUP($B21,月間集計シート!$AI:$AN,5,FALSE)<>0,VLOOKUP($B21,月間集計シート!$AI:$AN,5,FALSE)*24,"") -> 1 | L21: =IF(I21="","",IF(I21>=J21,I21-J21,I21)) -> 9
B22: =B21+1 -> 46217 | C22: =IF(B22<>"",WEEKDAY(B22),"") -> 3 | E22: =IF(U22<>"",U22,IF(C22=1,"公休",IF(C22=7,"公休",""))) | G22: =IF(VLOOKUP($B22,月間集計シート!$AI:$AN,3,FALSE)<>0,VLOOKUP($B22,月間集計シート!$AI:$AN,3,FALSE),"") -> 0.375 | H22: =IF(VLOOKUP($B22,月間集計シート!$AI:$AN,4,FALSE)<>0,VLOOKUP($B22,月間集計シート!$AI:$AN,4,FALSE),"") -> 0.79166667 | I22: =IF(G22="","",IF(H22="","",IF(HOUR(G22)+MINUTE(G22)/60<HOUR(H22)+MINUTE(H22)/60,(HOUR(H22)+MINUTE(H22)/60)-(HOUR(G22)+MINUTE(G22)/60),24-(HOUR(G22)+MINUTE(G22)/60)+(HOUR(H22)+MINUTE(H22)/60)))) -> 10 | J22: =IF(VLOOKUP($B22,月間集計シート!$AI:$AN,5,FALSE)<>0,VLOOKUP($B22,月間集計シート!$AI:$AN,5,FALSE)*24,"") -> 1 | L22: =IF(I22="","",IF(I22>=J22,I22-J22,I22)) -> 9
B23: =B22+1 -> 46218 | C23: =IF(B23<>"",WEEKDAY(B23),"") -> 4 | E23: =IF(U23<>"",U23,IF(C23=1,"公休",IF(C23=7,"公休",""))) | G23: =IF(VLOOKUP($B23,月間集計シート!$AI:$AN,3,FALSE)<>0,VLOOKUP($B23,月間集計シート!$AI:$AN,3,FALSE),"") -> 0.375 | H23: =IF(VLOOKUP($B23,月間集計シート!$AI:$AN,4,FALSE)<>0,VLOOKUP($B23,月間集計シート!$AI:$AN,4,FALSE),"") -> 0.79166667 | I23: =IF(G23="","",IF(H23="","",IF(HOUR(G23)+MINUTE(G23)/60<HOUR(H23)+MINUTE(H23)/60,(HOUR(H23)+MINUTE(H23)/60)-(HOUR(G23)+MINUTE(G23)/60),24-(HOUR(G23)+MINUTE(G23)/60)+(HOUR(H23)+MINUTE(H23)/60)))) -> 10 | J23: =IF(VLOOKUP($B23,月間集計シート!$AI:$AN,5,FALSE)<>0,VLOOKUP($B23,月間集計シート!$AI:$AN,5,FALSE)*24,"") -> 1 | L23: =IF(I23="","",IF(I23>=J23,I23-J23,I23)) -> 9
... B27: =B26+1 -> 46222 | C27: =IF(B27<>"",WEEKDAY(B27),"") -> 1 | E27: =IF(U27<>"",U27,IF(C27=1,"公休",IF(C27=7,"公休",""))) -> 公休 | G27: =IF(VLOOKUP($B27,月間集計シート!$AI:$AN,3,FALSE)<>0,VLOOKUP($B27,月間集計シート!$AI:$AN,3,FALSE),"") | H27: =IF(VLOOKUP($B27,月間集計シート!$AI:$AN,4,FALSE)<>0,VLOOKUP($B27,月間集計シート!$AI:$AN,4,FALSE),"") | I27: =IF(G27="","",IF(H27="","",IF(HOUR(G27)+MINUTE(G27)/60<HOUR(H27)+MINUTE(H27)/60,(HOUR(H27)+MINUTE(H27)/60)-(HOUR(G27)+MINUTE(G27)/60),24-(HOUR(G27)+MINUTE(G27)/60)+(HOUR(H27)+MINUTE(H27)/60)))) | J27: =IF(VLOOKUP($B27,月間集計シート!$AI:$AN,5,FALSE)<>0,VLOOKUP($B27,月間集計シート!$AI:$AN,5,FALSE)*24,"") | L27: =IF(I27="","",IF(I27>=J27,I27-J27,I27))
B28: =B27+1 -> 46223 | C28: =IF(B28<>"",WEEKDAY(B28),"") -> 2 | E28: =IF(U28<>"",U28,IF(C28=1,"公休",IF(C28=7,"公休",""))) -> 公休 | G28: =IF(VLOOKUP($B28,月間集計シート!$AI:$AN,3,FALSE)<>0,VLOOKUP($B28,月間集計シート!$AI:$AN,3,FALSE),"") -> 0.375 | H28: =IF(VLOOKUP($B28,月間集計シート!$AI:$AN,4,FALSE)<>0,VLOOKUP($B28,月間集計シート!$AI:$AN,4,FALSE),"") -> 0.79166667 | I28: =IF(G28="","",IF(H28="","",IF(HOUR(G28)+MINUTE(G28)/60<HOUR(H28)+MINUTE(H28)/60,(HOUR(H28)+MINUTE(H28)/60)-(HOUR(G28)+MINUTE(G28)/60),24-(HOUR(G28)+MINUTE(G28)/60)+(HOUR(H28)+MINUTE(H28)/60)))) -> 10 | J28: =IF(VLOOKUP($B28,月間集計シート!$AI:$AN,5,FALSE)<>0,VLOOKUP($B28,月間集計シート!$AI:$AN,5,FALSE)*24,"") -> 1 | L28: =IF(I28="","",IF(I28>=J28,I28-J28,I28)) -> 9 | U28: 公休
B29: =B28+1 -> 46224 | C29: =IF(B29<>"",WEEKDAY(B29),"") -> 3 | E29: =IF(U29<>"",U29,IF(C29=1,"公休",IF(C29=7,"公休",""))) | G29: =IF(VLOOKUP($B29,月間集計シート!$AI:$AN,3,FALSE)<>0,VLOOKUP($B29,月間集計シート!$AI:$AN,3,FALSE),"") -> 0.375 | H29: =IF(VLOOKUP($B29,月間集計シート!$AI:$AN,4,FALSE)<>0,VLOOKUP($B29,月間集計シート!$AI:$AN,4,FALSE),"") -> 0.79166667 | I29: =IF(G29="","",IF(H29="","",IF(HOUR(G29)+MINUTE(G29)/60<HOUR(H29)+MINUTE(H29)/60,(HOUR(H29)+MINUTE(H29)/60)-(HOUR(G29)+MINUTE(G29)/60),24-(HOUR(G29)+MINUTE(G29)/60)+(HOUR(H29)+MINUTE(H29)/60)))) -> 10 | J29: =IF(VLOOKUP($B29,月間集計シート!$AI:$AN,5,FALSE)<>0,VLOOKUP($B29,月間集計シート!$AI:$AN,5,FALSE)*24,"") -> 1 | L29: =IF(I29="","",IF(I29>=J29,I29-J29,I29)) -> 9
B30: =B29+1 -> 46225 | C30: =IF(B30<>"",WEEKDAY(B30),"") -> 4 | E30: =IF(U30<>"",U30,IF(C30=1,"公休",IF(C30=7,"公休",""))) | G30: =IF(VLOOKUP($B30,月間集計シート!$AI:$AN,3,FALSE)<>0,VLOOKUP($B30,月間集計シート!$AI:$AN,3,FALSE),"") -> 0.375 | H30: =IF(VLOOKUP($B30,月間集計シート!$AI:$AN,4,FALSE)<>0,VLOOKUP($B30,月間集計シート!$AI:$AN,4,FALSE),"") -> 0.79166667 | I30: =IF(G30="","",IF(H30="","",IF(HOUR(G30)+MINUTE(G30)/60<HOUR(H30)+MINUTE(H30)/60,(HOUR(H30)+MINUTE(H30)/60)-(HOUR(G30)+MINUTE(G30)/60),24-(HOUR(G30)+MINUTE(G30)/60)+(HOUR(H30)+MINUTE(H30)/60)))) -> 10 | J30: =IF(VLOOKUP($B30,月間集計シート!$AI:$AN,5,FALSE)<>0,VLOOKUP($B30,月間集計シート!$AI:$AN,5,FALSE)*24,"") -> 1 | L30: =IF(I30="","",IF(I30>=J30,I30-J30,I30)) -> 9
B31: =B30+1 -> 46226 | C31: =IF(B31<>"",WEEKDAY(B31),"") -> 5 | E31: =IF(U31<>"",U31,IF(C31=1,"公休",IF(C31=7,"公休",""))) | G31: =IF(VLOOKUP($B31,月間集計シート!$AI:$AN,3,FALSE)<>0,VLOOKUP($B31,月間集計シート!$AI:$AN,3,FALSE),"") -> 0.375 | H31: =IF(VLOOKUP($B31,月間集計シート!$AI:$AN,4,FALSE)<>0,VLOOKUP($B31,月間集計シート!$AI:$AN,4,FALSE),"") -> 0.79166667 | I31: =IF(G31="","",IF(H31="","",IF(HOUR(G31)+MINUTE(G31)/60<HOUR(H31)+MINUTE(H31)/60,(HOUR(H31)+MINUTE(H31)/60)-(HOUR(G31)+MINUTE(G31)/60),24-(HOUR(G31)+MINUTE(G31)/60)+(HOUR(H31)+MINUTE(H31)/60)))) -> 10 | J31: =IF(VLOOKUP($B31,月間集計シート!$AI:$AN,5,FALSE)<>0,VLOOKUP($B31,月間集計シート!$AI:$AN,5,FALSE)*24,"") -> 1 | L31: =IF(I31="","",IF(I31>=J31,I31-J31,I31)) -> 9
B32: =B31+1 -> 46227 | C32: =IF(B32<>"",WEEKDAY(B32),"") -> 6 | E32: =IF(U32<>"",U32,IF(C32=1,"公休",IF(C32=7,"公休",""))) | G32: =IF(VLOOKUP($B32,月間集計シート!$AI:$AN,3,FALSE)<>0,VLOOKUP($B32,月間集計シート!$AI:$AN,3,FALSE),"") -> 0.375 | H32: =IF(VLOOKUP($B32,月間集計シート!$AI:$AN,4,FALSE)<>0,VLOOKUP($B32,月間集計シート!$AI:$AN,4,FALSE),"") -> 0.79166667 | I32: =IF(G32="","",IF(H32="","",IF(HOUR(G32)+MINUTE(G32)/60<HOUR(H32)+MINUTE(H32)/60,(HOUR(H32)+MINUTE(H32)/60)-(HOUR(G32)+MINUTE(G32)/60),24-(HOUR(G32)+MINUTE(G32)/60)+(HOUR(H32)+MINUTE(H32)/60)))) -> 10 | J32: =IF(VLOOKUP($B32,月間集計シート!$AI:$AN,5,FALSE)<>0,VLOOKUP($B32,月間集計シート!$AI:$AN,5,FALSE)*24,"") -> 1 | L32: =IF(I32="","",IF(I32>=J32,I32-J32,I32)) -> 9
B33: =B32+1 -> 46228 | C33: =IF(B33<>"",WEEKDAY(B33),"") -> 7 | E33: =IF(U33<>"",U33,IF(C33=1,"公休",IF(C33=7,"公休",""))) -> 公休 | G33: =IF(VLOOKUP($B33,月間集計シート!$AI:$AN,3,FALSE)<>0,VLOOKUP($B33,月間集計シート!$AI:$AN,3,FALSE),"") | H33: =IF(VLOOKUP($B33,月間集計シート!$AI:$AN,4,FALSE)<>0,VLOOKUP($B33,月間集計シート!$AI:$AN,4,FALSE),"") | I33: =IF(G33="","",IF(H33="","",IF(HOUR(G33)+MINUTE(G33)/60<HOUR(H33)+MINUTE(H33)/60,(HOUR(H33)+MINUTE(H33)/60)-(HOUR(G33)+MINUTE(G33)/60),24-(HOUR(G33)+MINUTE(G33)/60)+(HOUR(H33)+MINUTE(H33)/60)))) | J33: =IF(VLOOKUP($B33,月間集計シート!$AI:$AN,5,FALSE)<>0,VLOOKUP($B33,月間集計シート!$AI:$AN,5,FALSE)*24,"") | L33: =IF(I33="","",IF(I33>=J33,I33-J33,I33))
B34: =B33+1 -> 46229 | C34: =IF(B34<>"",WEEKDAY(B34),"") -> 1 | E34: =IF(U34<>"",U34,IF(C34=1,"公休",IF(C34=7,"公休",""))) -> 公休 | G34: =IF(VLOOKUP($B34,月間集計シート!$AI:$AN,3,FALSE)<>0,VLOOKUP($B34,月間集計シート!$AI:$AN,3,FALSE),"") | H34: =IF(VLOOKUP($B34,月間集計シート!$AI:$AN,4,FALSE)<>0,VLOOKUP($B34,月間集計シート!$AI:$AN,4,FALSE),"") | I34: =IF(G34="","",IF(H34="","",IF(HOUR(G34)+MINUTE(G34)/60<HOUR(H34)+MINUTE(H34)/60,(HOUR(H34)+MINUTE(H34)/60)-(HOUR(G34)+MINUTE(G34)/60),24-(HOUR(G34)+MINUTE(G34)/60)+(HOUR(H34)+MINUTE(H34)/60)))) | J34: =IF(VLOOKUP($B34,月間集計シート!$AI:$AN,5,FALSE)<>0,VLOOKUP($B34,月間集計シート!$AI:$AN,5,FALSE)*24,"") | L34: =IF(I34="","",IF(I34>=J34,I34-J34,I34))
B35: =B34+1 -> 46230 | C35: =IF(B35<>"",WEEKDAY(B35),"") -> 2 | E35: =IF(U35<>"",U35,IF(C35=1,"公休",IF(C35=7,"公休",""))) | G35: =IF(VLOOKUP($B35,月間集計シート!$AI:$AN,3,FALSE)<>0,VLOOKUP($B35,月間集計シート!$AI:$AN,3,FALSE),"") -> 0.375 | H35: =IF(VLOOKUP($B35,月間集計シート!$AI:$AN,4,FALSE)<>0,VLOOKUP($B35,月間集計シート!$AI:$AN,4,FALSE),"") -> 0.79166667 | I35: =IF(G35="","",IF(H35="","",IF(HOUR(G35)+MINUTE(G35)/60<HOUR(H35)+MINUTE(H35)/60,(HOUR(H35)+MINUTE(H35)/60)-(HOUR(G35)+MINUTE(G35)/60),24-(HOUR(G35)+MINUTE(G35)/60)+(HOUR(H35)+MINUTE(H35)/60)))) -> 10 | J35: =IF(VLOOKUP($B35,月間集計シート!$AI:$AN,5,FALSE)<>0,VLOOKUP($B35,月間集計シート!$AI:$AN,5,FALSE)*24,"") -> 1 | L35: =IF(I35="","",IF(I35>=J35,I35-J35,I35)) -> 9
B36: =B35+1 -> 46231 | C36: =IF(B36<>"",WEEKDAY(B36),"") -> 3 | E36: =IF(U36<>"",U36,IF(C36=1,"公休",IF(C36=7,"公休",""))) | G36: =IF(VLOOKUP($B36,月間集計シート!$AI:$AN,3,FALSE)<>0,VLOOKUP($B36,月間集計シート!$AI:$AN,3,FALSE),"") -> 0.375 | H36: =IF(VLOOKUP($B36,月間集計シート!$AI:$AN,4,FALSE)<>0,VLOOKUP($B36,月間集計シート!$AI:$AN,4,FALSE),"") -> 0.79166667 | I36: =IF(G36="","",IF(H36="","",IF(HOUR(G36)+MINUTE(G36)/60<HOUR(H36)+MINUTE(H36)/60,(HOUR(H36)+MINUTE(H36)/60)-(HOUR(G36)+MINUTE(G36)/60),24-(HOUR(G36)+MINUTE(G36)/60)+(HOUR(H36)+MINUTE(H36)/60)))) -> 10 | J36: =IF(VLOOKUP($B36,月間集計シート!$AI:$AN,5,FALSE)<>0,VLOOKUP($B36,月間集計シート!$AI:$AN,5,FALSE)*24,"") -> 1 | L36: =IF(I36="","",IF(I36>=J36,I36-J36,I36)) -> 9
B37: =IF(MONTH(B36+1)=I1,B36+1,"") -> 46232 | C37: =IF(B37<>"",WEEKDAY(B37),"") -> 4 | E37: =IF(U37<>"",U37,IF(C37=1,"公休",IF(C37=7,"公休",""))) | G37: =IF(ISNA(VLOOKUP($B37,月間集計シート!$AI:$AN,3,FALSE)),"",IF(VLOOKUP($B37,月間集計シート!$AI:$AN,3,FALSE)<>0,VLOOKUP($B37,月間集計シート!$AI:$AN,3,FALSE),"")) | H37: =IF(ISNA(VLOOKUP($B37,月間集計シート!$AI:$AN,4,FALSE)),"",IF(VLOOKUP($B37,月間集計シート!$AI:$AN,4,FALSE)<>0,VLOOKUP($B37,月間集計シート!$AI:$AN,4,FALSE),"")) | I37: =IF(G37="","",IF(H37="","",IF(HOUR(G37)+MINUTE(G37)/60<HOUR(H37)+MINUTE(H37)/60,(HOUR(H37)+MINUTE(H37)/60)-(HOUR(G37)+MINUTE(G37)/60),24-(HOUR(G37)+MINUTE(G37)/60)+(HOUR(H37)+MINUTE(H37)/60)))) | J37: =IF(VLOOKUP($B37,月間集計シート!$AI:$AN,5,FALSE)<>0,VLOOKUP($B37,月間集計シート!$AI:$AN,5,FALSE)*24,"") | L37: =IF(I37="","",IF(I37>=J37,I37-J37,I37))
B38: =IF(MONTH(B36+2)=I1,B37+1,"") -> 46233 | C38: =IF(B38<>"",WEEKDAY(B38),"") -> 5 | E38: =IF(U38<>"",U38,IF(C38=1,"公休",IF(C38=7,"公休",""))) | G38: =IF(ISNA(VLOOKUP($B38,月間集計シート!$AI:$AN,3,FALSE)),"",IF(VLOOKUP($B38,月間集計シート!$AI:$AN,3,FALSE)<>0,VLOOKUP($B38,月間集計シート!$AI:$AN,3,FALSE),"")) | H38: =IF(ISNA(VLOOKUP($B38,月間集計シート!$AI:$AN,4,FALSE)),"",IF(VLOOKUP($B38,月間集計シート!$AI:$AN,4,FALSE)<>0,VLOOKUP($B38,月間集計シート!$AI:$AN,4,FALSE),"")) | I38: =IF(G38="","",IF(H38="","",IF(HOUR(G38)+MINUTE(G38)/60<HOUR(H38)+MINUTE(H38)/60,(HOUR(H38)+MINUTE(H38)/60)-(HOUR(G38)+MINUTE(G38)/60),24-(HOUR(G38)+MINUTE(G38)/60)+(HOUR(H38)+MINUTE(H38)/60)))) | J38: =IF(VLOOKUP($B38,月間集計シート!$AI:$AN,5,FALSE)<>0,VLOOKUP($B38,月間集計シート!$AI:$AN,5,FALSE)*24,"") | L38: =IF(I38="","",IF(I38>=J38,I38-J38,I38))
G39: =IF(ISNA(VLOOKUP($B39,月間集計シート!$AI:$AN,3,FALSE)),"",IF(VLOOKUP($B39,月間集計シート!$AI:$AN,3,FALSE)<>0,VLOOKUP($B39,月間集計シート!$AI:$AN,3,FALSE),"")) | H39: =IF(ISNA(VLOOKUP($B39,月間集計シート!$AI:$AN,4,FALSE)),"",IF(VLOOKUP($B39,月間集計シート!$AI:$AN,4,FALSE)<>0,VLOOKUP($B39,月間集計シート!$AI:$AN,4,FALSE),"")) | I39: =IF(G39="","",IF(H39="","",IF(HOUR(G39)+MINUTE(G39)/60<HOUR(H39)+MINUTE(H39)/60,(HOUR(H39)+MINUTE(H39)/60)-(HOUR(G39)+MINUTE(G39)/60),24-(HOUR(G39)+MINUTE(G39)/60)+(HOUR(H39)+MINUTE(H39)/60)))) | J39: =IF(VLOOKUP($B39,月間集計シート!$AI:$AN,5,FALSE)<>0,VLOOKUP($B39,月間集計シート!$AI:$AN,5,FALSE)*24,"") -> #N/A | L39: =IF(I39="","",IF(I39>=J39,I39-J39,I39))
B40: 合 計 | M40: ③ | T40: =月間集計シート!AN46*24 -> 198
E41: ① | F41: =31-COUNTIF(E9:E39,"") -> 9 | L41: =SUM(L9:L39) -> 180 | M41: =SUM(M9:M39) -> 0 | T41: =月間集計シート!U28*24 -> 199.5
B44: {暦日数－(休日数①)}×7.5＝所定勤務時間数
B45: ="{ " & DAY(DATE(T9,I1+1,1)-1) & " －(① " & F41 & " )}×7.5＝ " & TEXT((DAY(DATE(T9,I1+1,1)-1)-F41)*7.5,"0.00") -> { 31 －(① 9 )}×7.5＝ 165.00
B46: ②就業時間－所定勤務時間数＝残業時間数 | Q46: ＴＯＴＡＬ
B47: ② | C47: =L41 -> 180 | E47: － | G47: =(DAY(DATE(T9,I1+1,1)-1)-F41)*7.5 -> 165 | H47: ＝ | I47: =C47-G47 -> 15 | Q47: =I47 -> 15
...

Sheet 会社名
A1: 会社コード | B1: 会社名 | C1: 備考
A2: 10001 | B2: FPTソフトウェア
A3: 10000 | B3: FPTジャパン

Sheet 氏名
A1: 支払先コード | B1: 会社名 | C1: Role | D1: 氏名
A2: 87990 | B2: FPTジャパン | C2: PM | D2: Nguyen Quoc Bao | E2: 日本
A3: 87990 | B3: FPTジャパン | C3: Consuitant | D3: 浅井 あき​ | E3: 日本
A4: 87990 | B4: FPTジャパン | C4: BA | D4: 大友 光理​ | E4: 日本
A5: 87990 | B5: FPTジャパン | C5: Front SE | D5: Do Hong Hieu​ | E5: 日本
A6: 87990 | B6: FPTジャパン | C6: BA | D6: Doan Huu Thuong | E6: 日本
A7: 87990 | B7: FPTジャパン | C7: Front SE | D7: 平田 | E7: 日本
A8: 87990 | B8: FPTジャパン | C8: PMO | D8: 志平 | E8: 日本
A9: 87990 | B9: FPTジャパン | C9: BA | D9: Phan Van HOAN​ | E9: ベトナム
A10: 87990 | B10: FPTジャパン | C10: BA | D10: Phung Thi THAO​ | E10: ベトナム
A11: 87990 | B11: FPTジャパン | C11: BA | D11: Tran Viet THANG​ | E11: ベトナム
A12: 87990 | B12: FPTジャパン | C12: BA | D12: Tran Nguyen Tien SU | E12: ベトナム
A13: 87990 | B13: FPTジャパン | C13: Comter | D13: Dinh Viet Ha | E13: ベトナム
A14: 87990 | B14: FPTジャパン | C14: BA | D14: Nguyen Hoang Nam | E14: ベトナム

Sheet 月間集計シート
A1: 月間集計シート（サンプル） | X1: ↓②当月の所定勤務日数を入力します
N2: 月曜 | O2: 火曜 | P2: 水曜 | Q2: 木曜 | R2: 金曜 | S2: 土曜 | T2: 日曜 | U2: 時間 | AA2: ＜業務管理用週別集計＞ | AI2: ='1週'!B3 -> 2026 | AJ2: ='1週'!C3 -> 7
A3: no | B3: 会社名 | C3: 氏名 | I3: ↓①集計プロジェクトコードを入力します。重複すると正しく集計できません。 | T3: =IF(U3=U28,"明細計と一致しています→","明細計と一致しません→") -> 明細計と一致しません→ | U3: =SUM(U4:U24) -> 0 | V3: 比率 | W3: 所定時間 | X3: 所定日数 | Z3: 38期製品開発部Project一覧 | AA3: 第1週 | AB3: 第2週 | AC3: 第3週 | AD3: 第4週 | AE3: 第5週 | AF3: 第6週 | AG3: シート | AI3: 日付 | AJ3: 曜 | AK3: 始業 | AL3: 就業 | AM3: 休憩 | AN3: 合計
